Workbook

Sheet Registro de incidencias
B2: Nombre del proyecto | C2: SIGRO · Sistema de Gestión de Recursos de Obra
B3: Organización | C3: SEVENS INGENIEROS SAC (RUC 20606456892) | F3: HU / tarea | G3: Solución
B4: Solución | C4: Web de oficina (React), app Android del almacenero que registra sin señal, API FastAPI + PostgreSQL y microservicios de Integraciones (S10, SUNAT, RENIEC) y Notificaciones
B5: Objetivo del proyecto | C5: Mejorar el control operativo de los recursos de obra —materiales, herramientas y horas hombre— de SEVENS INGENIEROS SAC, para reducir las interrupciones de obra por falta de material y el capital inmovilizado en material que sobra
B6: |No. sprint | C6: 1 | G6: Objetivo del Sprint | H6: El objetivo del primer sprint es poder controlar los recursos de la obra: desde lo que pide el S10 hasta lo que se compra, se consume y cuesta.
B8: Fecha | C8: Incidencia | D8: Persona relacionada | E8: Rol | F8: Artefacto relacionado | G8: Solución | H8: Referencia
B9: 15/10/2026 | C9: El docente redujo el curso de tres a dos sprints | D9: Omar Loaiza | E9: Docente | F9: Cronograma del Project Charter | G9: Se replanificó: Sprint 1 del 15 al 28/10 y Sprint 2 del 29/10 al 11/11 | H9: Indicación en clase, 15/10
B10: 16/10/2026 | C10: La mano de obra entra al alcance (antes estaba fuera, decisión D6) | D10: Fernando Istaña | E10: Scrum Master | F10: Product Backlog | G10: Nueva épica E7 limitada al tareo: HU-62 a HU-65 | H10: Acuerdo del equipo, 16/10
B11: 21/10/2026 | C11: Faltaban los reportes del S10 y bloqueaban la importación (HU-07, 16, 17 y 19) | D11: Pool Briones | E11: Cliente | F11: HU-07, HU-16, HU-17, HU-19 | G11: El cliente entregó Presupuesto, APU y Relación de insumos del presupuesto 2701006 | H11: Reportes 5.1, 5.2 y 5.3 del S10
B12: 21/10/2026 | C12: El objetivo del sprint hablaba de «compras» y de «presupuestado» | D12: Ing. Junior Cercado | E12: Revisor | F12: Objetivo del Sprint 1 | G12: Se redactó con «ingresos y salidas», «planificado» y horas hombre medidas contra las planificadas | H12: Corrección del 21/10
B13: 22/10/2026 | C13: Compras y proveedores tenían el actor equivocado (almacenero en vez de residente) | D13: Pool Briones | E13: Cliente | F13: HU-29, HU-30, HU-31, HU-32 | G13: Ficha de cambio CR-05: el actor pasa a residente de obra | H13: Respuesta del cliente por WhatsApp, 22/10
B14: 22/10/2026 | C14: Requisito nuevo del cliente: un formato para pedir materiales | D14: Pool Briones | E14: Cliente | F14: Product Backlog | G14: Ficha CR-04: «solicitud de materiales», HU-66 y HU-67 en el Sprint 2 | H14: Respuesta del cliente por WhatsApp, 22/10
B15: 22/10/2026 | C15: El repositorio de GitHub está público y contiene datos del cliente | D15: Fernando Istaña | E15: Scrum Master | F15: Repositorio xteban-sp/sevens-sigro | G15: Pasarlo a privado e invitar al docente como lector (T-237) | H15: Auditoría de coherencia, 22/10
B16: 22/10/2026 | C16: El microservicio de integraciones no autenticaba a quien lo llamaba | D16: Fernando Istaña | E16: Developer (integraciones) | F16: integraciones/main.py | G16: Token de servicio X-Servicio-Token obligatorio cuando se configura | H16: Revisión del avance de Adiel, 22/10
B17: 22/10/2026 | C17: Sin Docker en el equipo de desarrollo: docker compose sin construir ni desplegar | D17: Víctor Adiel Luján | E17: Product Owner / backend | F17: docker-compose.yml | G17: Fernando asume el despliegue del ambiente de pruebas (T-233) | H17: Avance de Adiel, 22/10
B18: 22/10/2026 | C18: uvicorn no se encontraba en el PATH de Windows al levantar el microservicio | D18: Fernando Istaña | E18: Developer (integraciones) | F18: integraciones/ | G18: Se levanta con «py -m uvicorn main:app --port 8001 --env-file .env» | H18: integraciones/LEEME.md
B19: 22/10/2026 | C19: Aviso de seguridad: certificados de una autoridad comprometida en certifi | D19: Fernando Istaña | E19: Developer (integraciones) | F19: integraciones/requirements.txt | G19: Se exige certifi>=2026.10.19 | H19: Aviso de seguridad de octubre de 2026
... B24: 22/10/2026 | C24: Cambio de reparto: Henry pasa a la web y Adiel toma todo el backend | D24: Henry Ticona | E24: Developer | F24: equipo/henry.md y CLAUDE.md | G24: Guía de arranque de Henry y tablero con responsables actualizados | H24: Rama scrum-tablero-sprint-1

Sheet Bitácora de trabajo
B3: Nombre del proyecto | C3: SIGRO · Sistema de Gestión de Recursos de Obra
B4: Organización | C4: SEVENS INGENIEROS SAC (RUC 20606456892)
B5: Solución | C5: Web de oficina (React), app Android del almacenero que registra sin señal, API FastAPI + PostgreSQL y microservicios de Integraciones (S10, SUNAT, RENIEC) y Notificaciones
B6: Objetivo del proyecto | C6: Mejorar el control operativo de los recursos de obra —materiales, herramientas y horas hombre— de SEVENS INGENIEROS SAC, para reducir las interrupciones de obra por falta de material y el capital inmovilizado en material que sobra
B7: |No. sprint | C7: 1 | D7: Objetivo del Sprint | E7: El objetivo del primer sprint es poder controlar los recursos de la obra: desde lo que pide el S10 hasta lo que se compra, se consume y cuesta.
B9: Día del proyecto | C9: Fecha | D9: Colaborador | E9: Rol | F9: Hora | G9: Descripción de la actividad | H9: Tarea
B10: Día 1 | C10: 15/10/2026 | D10: Equipo Scrum | E10: Scrum Team | G10: Sprint Planning: objetivo del Sprint 1 y selección de 29 historias | H10: Sprint Backlog
B11: Día 2 | C11: 16/10/2026 | D11: Fernando Istaña | E11: Scrum Master | G11: Incorporar la mano de obra al Product Backlog (épica E7) | H11: HU-62 a HU-65
B12: Día 7 | C12: 21/10/2026 | D12: Equipo Scrum | E12: Scrum Team | G12: Planning Poker: estimación de las historias con el voto de los cuatro integrantes | H12: Puntuación de las HU
B13: Día 7 | C13: 21/10/2026 | D13: Fernando Istaña | E13: Scrum Master / Developer | G13: Recibir los reportes del S10 y extraer el análisis de precios unitarios (6 902 filas, 1 217 partidas) | H13: T-069
B14: Día 7 | C14: 21/10/2026 | D14: Nicolás Pachamora | E14: Developer | G14: Diagramas de actividades del negocio (A1 a A4) y de estados (E1 a E3) | H14: T-259
B15: Día 7 | C15: 21/10/2026 | D15: Fernando Istaña | E15: Scrum Master | F15: 19:02 | G15: Subir al repositorio el contexto del proyecto, las historias del Sprint 1 y 2 y las reglas de dominio (commit) | H15: CLAUDE.md, docs/
B16: Día 7 | C16: 21/10/2026 | D16: Fernando Istaña | E16: Scrum Master | F16: 20:33 | G16: Subir las pantallas del Sprint 1, la estimación del equipo y los entregables (commit) | H16: Diseño UI
B17: Día 8 | C17: 22/10/2026 | D17: Fernando Istaña | E17: Developer (web e integraciones) | F17: 09:30 | G17: Web de oficina (pantallas e importador del S10), microservicio de integraciones (RUC, DNI, S10: 284 insumos, 0 fallidos), semillas reales del cliente y documentos Scrum (commit) | H17: T-023
B18: Día 8 | C18: 22/10/2026 | D18: Víctor Adiel Luján | E18: Product Owner / backend | F18: 10:21 | G18: API de obra, compras y tareo (629 pruebas) y microservicio de Notificaciones con outbox; PR #1 fusionado | H18: HU-01, 12–15, 29, 30, 32, 62, 63
B19: Día 8 | C19: 22/10/2026 | D19: Víctor Adiel Luján | E19: Product Owner / backend | F19: 10:35 | G19: Diagramas físico (con outbox), entidad-relación y esquema de microservicios (commit) | H19: Base de datos
B20: Día 8 | C20: 22/10/2026 | D20: Víctor Adiel Luján | E20: Product Owner / backend | F20: 12:07 | G20: Proveedor nuevo con RUC o DNI (decisión D-C5) y decisiones de la API ratificadas (commit) | H20: HU-30
B21: Día 8 | C21: 22/10/2026 | D21: Víctor Adiel Luján | E21: Product Owner / backend | F21: 15:07 | G21: Diagramas en draw.io editable; PR #2 fusionado a main | H21: Base de datos
B22: Día 8 | C22: 22/10/2026 | D22: Equipo Scrum | E22: Scrum Team | G22: Presentación al docente: puntuación de las HU, objetivo del sprint y tarjetas DoR y DoD; se recibe su retroalimentación | H22: Product Backlog y Sprint Backlog
B23: Día 8 | C23: 22/10/2026 | D23: Fernando Istaña | E23: Scrum Master | G23: Auditoría de coherencia y SWEBOK; corrección de 7 errores en los diagramas | H23: Modelado UML
B24: Día 8 | C24: 22/10/2026 | D24: Fernando Istaña | E24: Scrum Master | F24: 22:08 | G24: Tablero Scrum con las tareas por HU y guía de arranque de Henry en la web (commit en la rama scrum-tablero-sprint-1) | H24: T-253
B25: Día 8 | C25: 22/10/2026 | D25: Fernando Istaña | E25: Scrum Master | F25: 22:30 | G25: Tareas con el modelo del docente, registro de incidencias, bitácora e historias técnicas HT-01 a HT-08 (commit) | H25: T-253
B42: Horas tomadas de los commits del repositorio; donde está vacía la completa el colaborador. Del 23/10 en adelante, una fila por actividad: fecha · hora · colaborador · qué hizo · T-xxx.

Sheet Tablero (To Do · Doing · Done)
B2: Registro de tareas · Sprint 1 · To Do → Doing → Done
B3: Al mover una tarjeta se anota la fecha y se confirma el criterio. To Do → Doing: la HU cumple la DoR (L1–L12). Doing → Done: se cumple el criterio de la tarea; la HU queda Done solo cuando su «Aceptación» cumple la DoD (T1–T10 + condiciones finales). Máximo 2 tareas en Doing por persona. Lunes 27/10: todo en Done.
B5: ID | C5: HU | D5: Historia | E5: Fase | F5: Tarea | G5: Responsable | H5: Horas | I5: Límite | J5: Depende de | K5: Estado | L5: ¿DoR de la HU? | M5: Fecha a Doing | N5: Criterio para Done | O5: ¿Criterio cumplido? | P5: Fecha a Done | Q5: Evidencia (PR / enlace) | R5: Control | S5: n.º To Do | T5: n.º Doing | U5: n.º Done
B6: T-001 | C6: HU-01 | D6: Crear proyecto | E6: Diseño UI | F6: Diseñar la interfaz de usuario de HU-01: pantalla 9 · Crear la obra | G6: Fernando | H6: 1 | I6: 23/10 | K6: Done | L6: Sí | M6: 22/10/2026 | N6: Mockup en el lienzo, revisado por el equipo | O6: Sí | P6: 22/10/2026 | Q6: Lienzo «SIGRO · Pantallas y diagramas del Sprint 1» | R6: =IF(AND(K6<>"To Do",L6<>"Sí"),"⚠ pasó a Doing sin DoR",IF(AND(K6="Done",O6<>"Sí"),"⚠ Done sin criterio cumplido",IF(AND(K6="Doing",COUNTIFS($G$6:$G$266,G6,$K$6:$K$266,"Doing",$E$6:$E$266,"<>Scrum")>2,E6<>"Scrum"),"⚠ más de 2 en Doing","ok"))) | S6: =IF($K6="To Do",COUNTIF($K$6:$K6,"To Do"),"") | T6: =IF($K6="Doing",COUNTIF($K$6:$K6,"Doing"),"") | U6: =IF($K6="Done",COUNTIF($K$6:$K6,"Done"),"")
B7: T-002 | C7: HU-01 | D7: Crear proyecto | E7: Modelado UML | F7: Modelar la funcionalidad de HU-01 con el diagrama UML de estados de la obra (en ejecución → ampliada → cerrada) | G7: Fernando | H7: 1 | I7: 24/10 | J7: T-001 | K7: To Do | N7: Diagrama publicado en el repo o el lienzo | R7: =IF(AND(K7<>"To Do",L7<>"Sí"),"⚠ pasó a Doing sin DoR",IF(AND(K7="Done",O7<>"Sí"),"⚠ Done sin criterio cumplido",IF(AND(K7="Doing",COUNTIFS($G$6:$G$266,G7,$K$6:$K$266,"Doing",$E$6:$E$266,"<>Scrum")>2,E7<>"Scrum"),"⚠ más de 2 en Doing","ok"))) | S7: =IF($K7="To Do",COUNTIF($K$6:$K7,"To Do"),"") | T7: =IF($K7="Doing",COUNTIF($K$6:$K7,"Doing"),"") | U7: =IF($K7="Done",COUNTIF($K$6:$K7,"Done"),"")
B8: T-003 | C8: HU-01 | D8: Crear proyecto | E8: Base de datos | F8: Implementar las tablas asociadas a HU-01: proyecto, proyecto_plazo_historial | G8: Adiel | H8: 1 | I8: 24/10 | K8: Done | L8: Sí | M8: 22/10/2026 | N8: Migración fusionada, corre en base limpia y con datos, y se revierte | O8: Sí | P8: 22/10/2026 | Q8: PR #1 de Adiel (22/10) | R8: =IF(AND(K8<>"To Do",L8<>"Sí"),"⚠ pasó a Doing sin DoR",IF(AND(K8="Done",O8<>"Sí"),"⚠ Done sin criterio cumplido",IF(AND(K8="Doing",COUNTIFS($G$6:$G$266,G8,$K$6:$K$266,"Doing",$E$6:$E$266,"<>Scrum")>2,E8<>"Scrum"),"⚠ más de 2 en Doing","ok"))) | S8: =IF($K8="To Do",COUNTIF($K$6:$K8,"To Do"),"") | T8: =IF($K8="Doing",COUNTIF($K$6:$K8,"Doing"),"") | U8: =IF($K8="Done",COUNTIF($K$6:$K8,"Done"),"")
B9: T-004 | C9: HU-01 | D9: Crear proyecto | E9: Backend | F9: Programar el back-end de HU-01 (entidad, repositorio, servicio y controlador): el endpoint para crear la obra, validando nombre y plazo obligatorios, fin ≥ inicio y estado inicial «en ejecución» | G9: Adiel | H9: 2 | I9: 25/10 | K9: Done | L9: Sí | M9: 22/10/2026 | N9: PR fusionado con sus pruebas automáticas en verde y el endpoint documentado | O9: Sí | P9: 22/10/2026 | Q9: PR #1 y #2 de Adiel (22/10) | R9: =IF(AND(K9<>"To Do",L9<>"Sí"),"⚠ pasó a Doing sin DoR",IF(AND(K9="Done",O9<>"Sí"),"⚠ Done sin criterio cumplido",IF(AND(K9="Doing",COUNTIFS($G$6:$G$266,G9,$K$6:$K$266,"Doing",$E$6:$E$266,"<>Scrum")>2,E9<>"Scrum"),"⚠ más de 2 en Doing","ok"))) | S9: =IF($K9="To Do",COUNTIF($K$6:$K9,"To Do"),"") | T9: =IF($K9="Doing",COUNTIF($K$6:$K9,"Doing"),"") | U9: =IF($K9="Done",COUNTIF($K$6:$K9,"Done"),"")
B10: T-005 | C10: HU-01 | D10: Crear proyecto | E10: Triggers y funciones | F10: Implementar el CHECK de fecha de fin ≥ inicio en proyecto (HU-01) | G10: Adiel | H10: 1 | I10: 25/10 | J10: T-003 | K10: To Do | N10: Regla en la base con su prueba, en un PR fusionado | R10: =IF(AND(K10<>"To Do",L10<>"Sí"),"⚠ pasó a Doing sin DoR",IF(AND(K10="Done",O10<>"Sí"),"⚠ Done sin criterio cumplido",IF(AND(K10="Doing",COUNTIFS($G$6:$G$266,G10,$K$6:$K$266,"Doing",$E$6:$E$266,"<>Scrum")>2,E10<>"Scrum"),"⚠ más de 2 en Doing","ok"))) | S10: =IF($K10="To Do",COUNTIF($K$6:$K10,"To Do"),"") | T10: =IF($K10="Doing",COUNTIF($K$6:$K10,"Doing"),"") | U10: =IF($K10="Done",COUNTIF($K$6:$K10,"Done"),"")
B11: T-006 | C11: HU-01 | D11: Crear proyecto | E11: Front-end web | F11: Programar la pantalla web para crear la obra | G11: Fernando | H11: 2 | I11: 26/10 | K11: Done | L11: Sí | M11: 22/10/2026 | N11: PR fusionado, build sin errores, modo claro/oscuro y escala 125 % | O11: Sí | P11: 22/10/2026 | Q11: Commit del 22/10 09:30 (datos simulados) | R11: =IF(AND(K11<>"To Do",L11<>"Sí"),"⚠ pasó a Doing sin DoR",IF(AND(K11="Done",O11<>"Sí"),"⚠ Done sin criterio cumplido",IF(AND(K11="Doing",COUNTIFS($G$6:$G$266,G11,$K$6:$K$266,"Doing",$E$6:$E$266,"<>Scrum")>2,E11<>"Scrum"),"⚠ más de 2 en Doing","ok"))) | S11: =IF($K11="To Do",COUNTIF($K$6:$K11,"To Do"),"") | T11: =IF($K11="Doing",COUNTIF($K$6:$K11,"Doing"),"") | U11: =IF($K11="Done",COUNTIF($K$6:$K11,"Done"),"")
B12: T-007 | C12: HU-01 | D12: Crear proyecto | E12: Conexión API | F12: Conectar la pantalla «Crear la obra» con el endpoint real de la API | G12: Fernando | H12: 2 | I12: 26/10 | J12: T-004, T-006, T-240 | K12: To Do | N12: La pantalla muestra los datos reales del servidor y sus errores | R12: =IF(AND(K12<>"To Do",L12<>"Sí"),"⚠ pasó a Doing sin DoR",IF(AND(K12="Done",O12<>"Sí"),"⚠ Done sin criterio cumplido",IF(AND(K12="Doing",COUNTIFS($G$6:$G$266,G12,$K$6:$K$266,"Doing",$E$6:$E$266,"<>Scrum")>2,E12<>"Scrum"),"⚠ más de 2 en Doing","ok"))) | S12: =IF($K12="To Do",COUNTIF($K$6:$K12,"To Do"),"") | T12: =IF($K12="Doing",COUNTIF($K$6:$K12,"Doing"),"") | U12: =IF($K12="Done",COUNTIF($K$6:$K12,"Done"),"")
B13: T-008 | C13: HU-01 | D13: Crear proyecto | E13: Pruebas | F13: Probar la funcionalidad de HU-01 (la API con Postman y la pantalla web) contra cada condición final y aprobar su PR | G13: Henry | H13: 1 | I13: 27/10 | J13: T-003, T-004, T-005, T-006, T-007, T-233 | K13: To Do | N13: Cada condición final verificada con Postman y en la interfaz; PR aprobado por alguien distinto del autor | R13: =IF(AND(K13<>"To Do",L13<>"Sí"),"⚠ pasó a Doing sin DoR",IF(AND(K13="Done",O13<>"Sí"),"⚠ Done sin criterio cumplido",IF(AND(K13="Doing",COUNTIFS($G$6:$G$266,G13,$K$6:$K$266,"Doing",$E$6:$E$266,"<>Scrum")>2,E13<>"Scrum"),"⚠ más de 2 en Doing","ok"))) | S13: =IF($K13="To Do",COUNTIF($K$6:$K13,"To Do"),"") | T13: =IF($K13="Doing",COUNTIF($K$6:$K13,"Doing"),"") | U13: =IF($K13="Done",COUNTIF($K$6:$K13,"Done"),"")
B14: T-009 | C14: HU-01 | D14: Crear proyecto | E14: Aceptación | F14: Aceptar HU-01 como Product Owner desde la interfaz y moverla a Done | G14: Adiel | H14: 0.5 | I14: 27/10 | J14: T-008 | K14: To Do | N14: DoD T1–T10 + condiciones finales aceptadas por el PO → la HU pasa a Done | R14: =IF(AND(K14<>"To Do",L14<>"Sí"),"⚠ pasó a Doing sin DoR",IF(AND(K14="Done",O14<>"Sí"),"⚠ Done sin criterio cumplido",IF(AND(K14="Doing",COUNTIFS($G$6:$G$266,G14,$K$6:$K$266,"Doing",$E$6:$E$266,"<>Scrum")>2,E14<>"Scrum"),"⚠ más de 2 en Doing","ok"))) | S14: =IF($K14="To Do",COUNTIF($K$6:$K14,"To Do"),"") | T14: =IF($K14="Doing",COUNTIF($K$6:$K14,"Doing"),"") | U14: =IF($K14="Done",COUNTIF($K$6:$K14,"Done"),"")
B15: T-010 | C15: HU-03 | D15: Reportar la obra en semanas | E15: Diseño UI | F15: Diseñar la interfaz de usuario de HU-03: pantalla 9 · Crear la obra y 22 · Detalle de la obra | G15: Fernando | H15: 1 | I15: 23/10 | K15: Done | L15: Sí | M15: 22/10/2026 | N15: Mockup en el lienzo, revisado por el equipo | O15: Sí | P15: 22/10/2026 | Q15: Lienzo «SIGRO · Pantallas y diagramas del Sprint 1» | R15: =IF(AND(K15<>"To Do",L15<>"Sí"),"⚠ pasó a Doing sin DoR",IF(AND(K15="Done",O15<>"Sí"),"⚠ Done sin criterio cumplido",IF(AND(K15="Doing",COUNTIFS($G$6:$G$266,G15,$K$6:$K$266,"Doing",$E$6:$E$266,"<>Scrum")>2,E15<>"Scrum"),"⚠ más de 2 en Doing","ok"))) | S15: =IF($K15="To Do",COUNTIF($K$6:$K15,"To Do"),"") | T15: =IF($K15="Doing",COUNTIF($K$6:$K15,"Doing"),"") | U15: =IF($K15="Done",COUNTIF($K$6:$K15,"Done"),"")
B16: T-011 | C16: HU-03 | D16: Reportar la obra en semanas | E16: Modelado UML | F16: Modelar la funcionalidad de HU-03 con el diagrama UML de actividades de la generación de semanas | G16: Fernando | H16: 1 | I16: 24/10 | J16: T-010 | K16: To Do | N16: Diagrama publicado en el repo o el lienzo | R16: =IF(AND(K16<>"To Do",L16<>"Sí"),"⚠ pasó a Doing sin DoR",IF(AND(K16="Done",O16<>"Sí"),"⚠ Done sin criterio cumplido",IF(AND(K16="Doing",COUNTIFS($G$6:$G$266,G16,$K$6:$K$266,"Doing",$E$6:$E$266,"<>Scrum")>2,E16<>"Scrum"),"⚠ más de 2 en Doing","ok"))) | S16: =IF($K16="To Do",COUNTIF($K$6:$K16,"To Do"),"") | T16: =IF($K16="Doing",COUNTIF($K$6:$K16,"Doing"),"") | U16: =IF($K16="Done",COUNTIF($K$6:$K16,"Done"),"")
B17: T-012 | C17: HU-03 | D17: Reportar la obra en semanas | E17: Base de datos | F17: Implementar las tablas asociadas a HU-03: periodo | G17: Adiel | H17: 1 | I17: 24/10 | K17: Done | L17: Sí | M17: 22/10/2026 | N17: Migración fusionada, corre en base limpia y con datos, y se revierte | O17: Sí | P17: 22/10/2026 | Q17: PR #1 de Adiel (22/10) | R17: =IF(AND(K17<>"To Do",L17<>"Sí"),"⚠ pasó a Doing sin DoR",IF(AND(K17="Done",O17<>"Sí"),"⚠ Done sin criterio cumplido",IF(AND(K17="Doing",COUNTIFS($G$6:$G$266,G17,$K$6:$K$266,"Doing",$E$6:$E$266,"<>Scrum")>2,E17<>"Scrum"),"⚠ más de 2 en Doing","ok"))) | S17: =IF($K17="To Do",COUNTIF($K$6:$K17,"To Do"),"") | T17: =IF($K17="Doing",COUNTIF($K$6:$K17,"Doing"),"") | U17: =IF($K17="Done",COUNTIF($K$6:$K17,"Done"),"")
B18: T-013 | C18: HU-03 | D18: Reportar la obra en semanas | E18: Backend | F18: Programar el back-end de HU-03 (entidad, repositorio, servicio y controlador): la generación automática de semanas al crear la obra y al ampliar el plazo, con sus pruebas | G18: Adiel | H18: 2 | I18: 25/10 | K18: Done | L18: Sí | M18: 22/10/2026 | N18: PR fusionado con sus pruebas automáticas en verde y el endpoint documentado | O18: Sí | P18: 22/10/2026 | Q18: PR #1 y #2 de Adiel (22/10) | R18: =IF(AND(K18<>"To Do",L18<>"Sí"),"⚠ pasó a Doing sin DoR",IF(AND(K18="Done",O18<>"Sí"),"⚠ Done sin criterio cumplido",IF(AND(K18="Doing",COUNTIFS($G$6:$G$266,G18,$K$6:$K$266,"Doing",$E$6:$E$266,"<>Scrum")>2,E18<>"Scrum"),"⚠ más de 2 en Doing","ok"))) | S18: =IF($K18="To Do",COUNTIF($K$6:$K18,"To Do"),"") | T18: =IF($K18="Doing",COUNTIF($K$6:$K18,"Doing"),"") | U18: =IF($K18="Done",COUNTIF($K$6:$K18,"Done"),"")
B19: T-014 | C19: HU-03 | D19: Reportar la obra en semanas | E19: Front-end web | F19: Programar la tira de semanas en la web (cerrada, en curso, por venir) | G19: Fernando | H19: 2 | I19: 26/10 | K19: Done | L19: Sí | M19: 22/10/2026 | N19: PR fusionado, build sin errores, modo claro/oscuro y escala 125 % | O19: Sí | P19: 22/10/2026 | Q19: Commit del 22/10 09:30 (datos simulados) | R19: =IF(AND(K19<>"To Do",L19<>"Sí"),"⚠ pasó a Doing sin DoR",IF(AND(K19="Done",O19<>"Sí"),"⚠ Done sin criterio cumplido",IF(AND(K19="Doing",COUNTIFS($G$6:$G$266,G19,$K$6:$K$266,"Doing",$E$6:$E$266,"<>Scrum")>2,E19<>"Scrum"),"⚠ más de 2 en Doing","ok"))) | S19: =IF($K19="To Do",COUNTIF($K$6:$K19,"To Do"),"") | T19: =IF($K19="Doing",COUNTIF($K$6:$K19,"Doing"),"") | U19: =IF($K19="Done",COUNTIF($K$6:$K19,"Done"),"")
B20: T-015 | C20: HU-03 | D20: Reportar la obra en semanas | E20: Conexión API | F20: Conectar la tira de semanas con la API real | G20: Fernando | H20: 2 | I20: 26/10 | J20: T-013, T-014, T-240 | K20: To Do | N20: La pantalla muestra los datos reales del servidor y sus errores | R20: =IF(AND(K20<>"To Do",L20<>"Sí"),"⚠ pasó a Doing sin DoR",IF(AND(K20="Done",O20<>"Sí"),"⚠ Done sin criterio cumplido",IF(AND(K20="Doing",COUNTIFS($G$6:$G$266,G20,$K$6:$K$266,"Doing",$E$6:$E$266,"<>Scrum")>2,E20<>"Scrum"),"⚠ más de 2 en Doing","ok"))) | S20: =IF($K20="To Do",COUNTIF($K$6:$K20,"To Do"),"") | T20: =IF($K20="Doing",COUNTIF($K$6:$K20,"Doing"),"") | U20: =IF($K20="Done",COUNTIF($K$6:$K20,"Done"),"")
B21: T-016 | C21: HU-03 | D21: Reportar la obra en semanas | E21: Pruebas | F21: Probar la funcionalidad de HU-03 (la API con Postman y la pantalla web) contra cada condición final y aprobar su PR | G21: Henry | H21: 1 | I21: 27/10 | J21: T-012, T-013, T-014, T-015, T-233 | K21: To Do | N21: Cada condición final verificada con Postman y en la interfaz; PR aprobado por alguien distinto del autor | R21: =IF(AND(K21<>"To Do",L21<>"Sí"),"⚠ pasó a Doing sin DoR",IF(AND(K21="Done",O21<>"Sí"),"⚠ Done sin criterio cumplido",IF(AND(K21="Doing",COUNTIFS($G$6:$G$266,G21,$K$6:$K$266,"Doing",$E$6:$E$266,"<>Scrum")>2,E21<>"Scrum"),"⚠ más de 2 en Doing","ok"))) | S21: =IF($K21="To Do",COUNTIF($K$6:$K21,"To Do"),"") | T21: =IF($K21="Doing",COUNTIF($K$6:$K21,"Doing"),"") | U21: =IF($K21="Done",COUNTIF($K$6:$K21,"Done"),"")
B22: T-017 | C22: HU-03 | D22: Reportar la obra en semanas | E22: Aceptación | F22: Aceptar HU-03 como Product Owner desde la interfaz y moverla a Done | G22: Adiel | H22: 0.5 | I22: 27/10 | J22: T-016 | K22: To Do | N22: DoD T1–T10 + condiciones finales aceptadas por el PO → la HU pasa a Done | R22: =IF(AND(K22<>"To Do",L22<>"Sí"),"⚠ pasó a Doing sin DoR",IF(AND(K22="Done",O22<>"Sí"),"⚠ Done sin criterio cumplido",IF(AND(K22="Doing",COUNTIFS($G$6:$G$266,G22,$K$6:$K$266,"Doing",$E$6:$E$266,"<>Scrum")>2,E22<>"Scrum"),"⚠ más de 2 en Doing","ok"))) | S22: =IF($K22="To Do",COUNTIF($K$6:$K22,"To Do"),"") | T22: =IF($K22="Doing",COUNTIF($K$6:$K22,"Doing"),"") | U22: =IF($K22="Done",COUNTIF($K$6:$K22,"Done"),"")
B23: T-018 | C23: HU-07 | D23: Importar catálogo de insumos del S10 | E23: Diseño UI | F23: Diseñar la interfaz de usuario de HU-07: pantalla 11 · Importar el catálogo del S10 | G23: Fernando | H23: 1 | I23: 23/10 | K23: Done | L23: Sí | M23: 22/10/2026 | N23: Mockup en el lienzo, revisado por el equipo | O23: Sí | P23: 22/10/2026 | Q23: Lienzo «SIGRO · Pantallas y diagramas del Sprint 1» | R23: =IF(AND(K23<>"To Do",L23<>"Sí"),"⚠ pasó a Doing sin DoR",IF(AND(K23="Done",O23<>"Sí"),"⚠ Done sin criterio cumplido",IF(AND(K23="Doing",COUNTIFS($G$6:$G$266,G23,$K$6:$K$266,"Doing",$E$6:$E$266,"<>Scrum")>2,E23<>"Scrum"),"⚠ más de 2 en Doing","ok"))) | S23: =IF($K23="To Do",COUNTIF($K$6:$K23,"To Do"),"") | T23: =IF($K23="Doing",COUNTIF($K$6:$K23,"Doing"),"") | U23: =IF($K23="Done",COUNTIF($K$6:$K23,"Done"),"")
B24: T-019 | C24: HU-07 | D24: Importar catálogo de insumos del S10 | E24: Modelado UML | F24: Modelar la funcionalidad de HU-07 con el diagrama UML de secuencia de la importación del S10 por el microservicio | G24: Fernando | H24: 1 | I24: 24/10 | K24: Done | L24: Sí | M24: 22/10/2026 | N24: Diagrama publicado en el repo o el lienzo | O24: Sí | P24: 22/10/2026 | Q24: Lienzo del Sprint 1 | R24: =IF(AND(K24<>"To Do",L24<>"Sí"),"⚠ pasó a Doing sin DoR",IF(AND(K24="Done",O24<>"Sí"),"⚠ Done sin criterio cumplido",IF(AND(K24="Doing",COUNTIFS($G$6:$G$266,G24,$K$6:$K$266,"Doing",$E$6:$E$266,"<>Scrum")>2,E24<>"Scrum"),"⚠ más de 2 en Doing","ok"))) | S24: =IF($K24="To Do",COUNTIF($K$6:$K24,"To Do"),"") | T24: =IF($K24="Doing",COUNTIF($K$6:$K24,"Doing"),"") | U24: =IF($K24="Done",COUNTIF($K$6:$K24,"Done"),"")
B25: T-020 | C25: HU-07 | D25: Importar catálogo de insumos del S10 | E25: Base de datos | F25: Implementar las tablas asociadas a HU-07: insumo (crear/actualizar por código) | G25: Adiel | H25: 1 | I25: 24/10 | J25: T-019 | K25: To Do | N25: Migración fusionada, corre en base limpia y con datos, y se revierte | R25: =IF(AND(K25<>"To Do",L25<>"Sí"),"⚠ pasó a Doing sin DoR",IF(AND(K25="Done",O25<>"Sí"),"⚠ Done sin criterio cumplido",IF(AND(K25="Doing",COUNTIFS($G$6:$G$266,G25,$K$6:$K$266,"Doing",$E$6:$E$266,"<>Scrum")>2,E25<>"Scrum"),"⚠ más de 2 en Doing","ok"))) | S25: =IF($K25="To Do",COUNTIF($K$6:$K25,"To Do"),"") | T25: =IF($K25="Doing",COUNTIF($K$6:$K25,"Doing"),"") | U25: =IF($K25="Done",COUNTIF($K$6:$K25,"Done"),"")
B26: T-021 | C26: HU-07 | D26: Importar catálogo de insumos del S10 | E26: Backend | F26: Programar el back-end de HU-07 (entidad, repositorio, servicio y controlador): el endpoint que aplica la importación: crear o actualizar insumos por código sin tocar saldos | G26: Adiel | H26: 4 | I26: 25/10 | J26: T-020 | K26: To Do | N26: PR fusionado con sus pruebas automáticas en verde y el endpoint documentado | R26: =IF(AND(K26<>"To Do",L26<>"Sí"),"⚠ pasó a Doing sin DoR",IF(AND(K26="Done",O26<>"Sí"),"⚠ Done sin criterio cumplido",IF(AND(K26="Doing",COUNTIFS($G$6:$G$266,G26,$K$6:$K$266,"Doing",$E$6:$E$266,"<>Scrum")>2,E26<>"Scrum"),"⚠ más de 2 en Doing","ok"))) | S26: =IF($K26="To Do",COUNTIF($K$6:$K26,"To Do"),"") | T26: =IF($K26="Doing",COUNTIF($K$6:$K26,"Doing"),"") | U26: =IF($K26="Done",COUNTIF($K$6:$K26,"Done"),"")
B27: T-022 | C27: HU-07 | D27: Importar catálogo de insumos del S10 | E27: Backend | F27: Configurar la llamada de la API a Integraciones con el token de servicio en docker compose | G27: Adiel | H27: 4 | I27: 25/10 | J27: T-020 | K27: To Do | N27: PR fusionado con sus pruebas automáticas en verde y el endpoint documentado | R27: =IF(AND(K27<>"To Do",L27<>"Sí"),"⚠ pasó a Doing sin DoR",IF(AND(K27="Done",O27<>"Sí"),"⚠ Done sin criterio cumplido",IF(AND(K27="Doing",COUNTIFS($G$6:$G$266,G27,$K$6:$K$266,"Doing",$E$6:$E$266,"<>Scrum")>2,E27<>"Scrum"),"⚠ más de 2 en Doing","ok"))) | S27: =IF($K27="To Do",COUNTIF($K$6:$K27,"To Do"),"") | T27: =IF($K27="Doing",COUNTIF($K$6:$K27,"Doing"),"") | U27: =IF($K27="Done",COUNTIF($K$6:$K27,"Done"),"")
B28: T-023 | C28: HU-07 | D28: Importar catálogo de insumos del S10 | E28: Integración | F28: Programar el lector del PDF «Relación de insumos» del S10 en el microservicio — integración con S10 (relación de insumos) | G28: Fernando | H28: 4 | I28: 25/10 | K28: Done | L28: Sí | M28: 22/10/2026 | N28: Probado con el archivo o servicio real, PR fusionado | O28: Sí | P28: 22/10/2026 | Q28: Commit del 22/10 09:30 | R28: =IF(AND(K28<>"To Do",L28<>"Sí"),"⚠ pasó a Doing sin DoR",IF(AND(K28="Done",O28<>"Sí"),"⚠ Done sin criterio cumplido",IF(AND(K28="Doing",COUNTIFS($G$6:$G$266,G28,$K$6:$K$266,"Doing",$E$6:$E$266,"<>Scrum")>2,E28<>"Scrum"),"⚠ más de 2 en Doing","ok"))) | S28: =IF($K28="To Do",COUNTIF($K$6:$K28,"To Do"),"") | T28: =IF($K28="Doing",COUNTIF($K$6:$K28,"Doing"),"") | U28: =IF($K28="Done",COUNTIF($K$6:$K28,"Done"),"")
B29: T-024 | C29: HU-07 | D29: Importar catálogo de insumos del S10 | E29: Front-end web | F29: Programar la pantalla web «Importar del S10» con el resumen de creados, actualizados y fallidos | G29: Fernando | H29: 4 | I29: 26/10 | K29: Done | L29: Sí | M29: 22/10/2026 | N29: PR fusionado, build sin errores, modo claro/oscuro y escala 125 % | O29: Sí | P29: 22/10/2026 | Q29: Commit del 22/10 09:30 | R29: =IF(AND(K29<>"To Do",L29<>"Sí"),"⚠ pasó a Doing sin DoR",IF(AND(K29="Done",O29<>"Sí"),"⚠ Done sin criterio cumplido",IF(AND(K29="Doing",COUNTIFS($G$6:$G$266,G29,$K$6:$K$266,"Doing",$E$6:$E$266,"<>Scrum")>2,E29<>"Scrum"),"⚠ más de 2 en Doing","ok"))) | S29: =IF($K29="To Do",COUNTIF($K$6:$K29,"To Do"),"") | T29: =IF($K29="Doing",COUNTIF($K$6:$K29,"Doing"),"") | U29: =IF($K29="Done",COUNTIF($K$6:$K29,"Done"),"")
B30: T-025 | C30: HU-07 | D30: Importar catálogo de insumos del S10 | E30: Pruebas | F30: Probar la funcionalidad de HU-07 (la API con Postman y la pantalla web) contra cada condición final y aprobar su PR | G30: Henry | H30: 1 | I30: 27/10 | J30: T-020, T-021, T-022, T-023, T-024, T-233 | K30: To Do | N30: Cada condición final verificada con Postman y en la interfaz; PR aprobado por alguien distinto del autor | R30: =IF(AND(K30<>"To Do",L30<>"Sí"),"⚠ pasó a Doing sin DoR",IF(AND(K30="Done",O30<>"Sí"),"⚠ Done sin criterio cumplido",IF(AND(K30="Doing",COUNTIFS($G$6:$G$266,G30,$K$6:$K$266,"Doing",$E$6:$E$266,"<>Scrum")>2,E30<>"Scrum"),"⚠ más de 2 en Doing","ok"))) | S30: =IF($K30="To Do",COUNTIF($K$6:$K30,"To Do"),"") | T30: =IF($K30="Doing",COUNTIF($K$6:$K30,"Doing"),"") | U30: =IF($K30="Done",COUNTIF($K$6:$K30,"Done"),"")
B31: T-026 | C31: HU-07 | D31: Importar catálogo de insumos del S10 | E31: Aceptación | F31: Aceptar HU-07 como Product Owner desde la interfaz y moverla a Done | G31: Adiel | H31: 0.5 | I31: 27/10 | J31: T-025 | K31: To Do | N31: DoD T1–T10 + condiciones finales aceptadas por el PO → la HU pasa a Done | R31: =IF(AND(K31<>"To Do",L31<>"Sí"),"⚠ pasó a Doing sin DoR",IF(AND(K31="Done",O31<>"Sí"),"⚠ Done sin criterio cumplido",IF(AND(K31="Doing",COUNTIFS($G$6:$G$266,G31,$K$6:$K$266,"Doing",$E$6:$E$266,"<>Scrum")>2,E31<>"Scrum"),"⚠ más de 2 en Doing","ok"))) | S31: =IF($K31="To Do",COUNTIF($K$6:$K31,"To Do"),"") | T31: =IF($K31="Doing",COUNTIF($K$6:$K31,"Doing"),"") | U31: =IF($K31="Done",COUNTIF($K$6:$K31,"Done"),"")
B32: T-027 | C32: HU-08 | D32: Registrar insumos | E32: Diseño UI | F32: Diseñar la interfaz de usuario de HU-08: pantalla 16 · Catálogo e insumo | G32: Fernando | H32: 1 | I32: 23/10 | K32: Done | L32: Sí | M32: 22/10/2026 | N32: Mockup en el lienzo, revisado por el equipo | O32: Sí | P32: 22/10/2026 | Q32: Lienzo «SIGRO · Pantallas y diagramas del Sprint 1» | R32: =IF(AND(K32<>"To Do",L32<>"Sí"),"⚠ pasó a Doing sin DoR",IF(AND(K32="Done",O32<>"Sí"),"⚠ Done sin criterio cumplido",IF(AND(K32="Doing",COUNTIFS($G$6:$G$266,G32,$K$6:$K$266,"Doing",$E$6:$E$266,"<>Scrum")>2,E32<>"Scrum"),"⚠ más de 2 en Doing","ok"))) | S32: =IF($K32="To Do",COUNTIF($K$6:$K32,"To Do"),"") | T32: =IF($K32="Doing",COUNTIF($K$6:$K32,"Doing"),"") | U32: =IF($K32="Done",COUNTIF($K$6:$K32,"Done"),"")
B33: T-028 | C33: HU-08 | D33: Registrar insumos | E33: Modelado UML | F33: Modelar la funcionalidad de HU-08 con el diagrama UML de secuencia del alta de insumo con verificación de duplicado | G33: Fernando | H33: 1 | I33: 24/10 | J33: T-027 | K33: To Do | N33: Diagrama publicado en el repo o el lienzo | R33: =IF(AND(K33<>"To Do",L33<>"Sí"),"⚠ pasó a Doing sin DoR",IF(AND(K33="Done",O33<>"Sí"),"⚠ Done sin criterio cumplido",IF(AND(K33="Doing",COUNTIFS($G$6:$G$266,G33,$K$6:$K$266,"Doing",$E$6:$E$266,"<>Scrum")>2,E33<>"Scrum"),"⚠ más de 2 en Doing","ok"))) | S33: =IF($K33="To Do",COUNTIF($K$6:$K33,"To Do"),"") | T33: =IF($K33="Doing",COUNTIF($K$6:$K33,"Doing"),"") | U33: =IF($K33="Done",COUNTIF($K$6:$K33,"Done"),"")
B34: T-029 | C34: HU-08 | D34: Registrar insumos | E34: Base de datos | F34: Implementar las tablas asociadas a HU-08: insumo, insumo_nombre_comercial | G34: Adiel | H34: 1 | I34: 24/10 | J34: T-028 | K34: To Do | N34: Migración fusionada, corre en base limpia y con datos, y se revierte | R34: =IF(AND(K34<>"To Do",L34<>"Sí"),"⚠ pasó a Doing sin DoR",IF(AND(K34="Done",O34<>"Sí"),"⚠ Done sin criterio cumplido",IF(AND(K34="Doing",COUNTIFS($G$6:$G$266,G34,$K$6:$K$266,"Doing",$E$6:$E$266,"<>Scrum")>2,E34<>"Scrum"),"⚠ más de 2 en Doing","ok"))) | S34: =IF($K34="To Do",COUNTIF($K$6:$K34,"To Do"),"") | T34: =IF($K34="Doing",COUNTIF($K$6:$K34,"Doing"),"") | U34: =IF($K34="Done",COUNTIF($K$6:$K34,"Done"),"")
B35: T-030 | C35: HU-08 | D35: Registrar insumos | E35: Backend | F35: Programar el back-end de HU-08 (entidad, repositorio, servicio y controlador): el endpoint del catálogo: generar código único, rechazar duplicados y marcar «por verificar» | G35: Adiel | H35: 3 | I35: 25/10 | J35: T-029 | K35: To Do | N35: PR fusionado con sus pruebas automáticas en verde y el endpoint documentado | R35: =IF(AND(K35<>"To Do",L35<>"Sí"),"⚠ pasó a Doing sin DoR",IF(AND(K35="Done",O35<>"Sí"),"⚠ Done sin criterio cumplido",IF(AND(K35="Doing",COUNTIFS($G$6:$G$266,G35,$K$6:$K$266,"Doing",$E$6:$E$266,"<>Scrum")>2,E35<>"Scrum"),"⚠ más de 2 en Doing","ok"))) | S35: =IF($K35="To Do",COUNTIF($K$6:$K35,"To Do"),"") | T35: =IF($K35="Doing",COUNTIF($K$6:$K35,"Doing"),"") | U35: =IF($K35="Done",COUNTIF($K$6:$K35,"Done"),"")
B36: T-031 | C36: HU-08 | D36: Registrar insumos | E36: Front-end web | F36: Programar la pantalla web del catálogo para ver, dar de alta y editar insumos | G36: Fernando | H36: 3 | I36: 26/10 | K36: Done | L36: Sí | M36: 22/10/2026 | N36: PR fusionado, build sin errores, modo claro/oscuro y escala 125 % | O36: Sí | P36: 22/10/2026 | Q36: Commit del 22/10 09:30 (datos simulados) | R36: =IF(AND(K36<>"To Do",L36<>"Sí"),"⚠ pasó a Doing sin DoR",IF(AND(K36="Done",O36<>"Sí"),"⚠ Done sin criterio cumplido",IF(AND(K36="Doing",COUNTIFS($G$6:$G$266,G36,$K$6:$K$266,"Doing",$E$6:$E$266,"<>Scrum")>2,E36<>"Scrum"),"⚠ más de 2 en Doing","ok"))) | S36: =IF($K36="To Do",COUNTIF($K$6:$K36,"To Do"),"") | T36: =IF($K36="Doing",COUNTIF($K$6:$K36,"Doing"),"") | U36: =IF($K36="Done",COUNTIF($K$6:$K36,"Done"),"")
B37: T-032 | C37: HU-08 | D37: Registrar insumos | E37: Conexión API | F37: Conectar la pantalla del catálogo con la API real | G37: Fernando | H37: 3 | I37: 26/10 | J37: T-030, T-031, T-240 | K37: To Do | N37: La pantalla muestra los datos reales del servidor y sus errores | R37: =IF(AND(K37<>"To Do",L37<>"Sí"),"⚠ pasó a Doing sin DoR",IF(AND(K37="Done",O37<>"Sí"),"⚠ Done sin criterio cumplido",IF(AND(K37="Doing",COUNTIFS($G$6:$G$266,G37,$K$6:$K$266,"Doing",$E$6:$E$266,"<>Scrum")>2,E37<>"Scrum"),"⚠ más de 2 en Doing","ok"))) | S37: =IF($K37="To Do",COUNTIF($K$6:$K37,"To Do"),"") | T37: =IF($K37="Doing",COUNTIF($K$6:$K37,"Doing"),"") | U37: =IF($K37="Done",COUNTIF($K$6:$K37,"Done"),"")
B38: T-033 | C38: HU-08 | D38: Registrar insumos | E38: Pruebas | F38: Probar la funcionalidad de HU-08 (la API con Postman y la pantalla web) contra cada condición final y aprobar su PR | G38: Henry | H38: 1 | I38: 27/10 | J38: T-029, T-030, T-031, T-032, T-233 | K38: To Do | N38: Cada condición final verificada con Postman y en la interfaz; PR aprobado por alguien distinto del autor | R38: =IF(AND(K38<>"To Do",L38<>"Sí"),"⚠ pasó a Doing sin DoR",IF(AND(K38="Done",O38<>"Sí"),"⚠ Done sin criterio cumplido",IF(AND(K38="Doing",COUNTIFS($G$6:$G$266,G38,$K$6:$K$266,"Doing",$E$6:$E$266,"<>Scrum")>2,E38<>"Scrum"),"⚠ más de 2 en Doing","ok"))) | S38: =IF($K38="To Do",COUNTIF($K$6:$K38,"To Do"),"") | T38: =IF($K38="Doing",COUNTIF($K$6:$K38,"Doing"),"") | U38: =IF($K38="Done",COUNTIF($K$6:$K38,"Done"),"")
B39: T-034 | C39: HU-08 | D39: Registrar insumos | E39: Aceptación | F39: Aceptar HU-08 como Product Owner desde la interfaz y moverla a Done | G39: Adiel | H39: 0.5 | I39: 27/10 | J39: T-033 | K39: To Do | N39: DoD T1–T10 + condiciones finales aceptadas por el PO → la HU pasa a Done | R39: =IF(AND(K39<>"To Do",L39<>"Sí"),"⚠ pasó a Doing sin DoR",IF(AND(K39="Done",O39<>"Sí"),"⚠ Done sin criterio cumplido",IF(AND(K39="Doing",COUNTIFS($G$6:$G$266,G39,$K$6:$K$266,"Doing",$E$6:$E$266,"<>Scrum")>2,E39<>"Scrum"),"⚠ más de 2 en Doing","ok"))) | S39: =IF($K39="To Do",COUNTIF($K$6:$K39,"To Do"),"") | T39: =IF($K39="Doing",COUNTIF($K$6:$K39,"Doing"),"") | U39: =IF($K39="Done",COUNTIF($K$6:$K39,"Done"),"")
B40: T-035 | C40: HU-12 | D40: Loguear usuario | E40: Diseño UI | F40: Diseñar la interfaz de usuario de HU-12: pantalla 1 (app) y 20 (web) · Login | G40: Fernando | H40: 1 | I40: 23/10 | K40: Done | L40: Sí | M40: 22/10/2026 | N40: Mockup en el lienzo, revisado por el equipo | O40: Sí | P40: 22/10/2026 | Q40: Lienzo «SIGRO · Pantallas y diagramas del Sprint 1» | R40: =IF(AND(K40<>"To Do",L40<>"Sí"),"⚠ pasó a Doing sin DoR",IF(AND(K40="Done",O40<>"Sí"),"⚠ Done sin criterio cumplido",IF(AND(K40="Doing",COUNTIFS($G$6:$G$266,G40,$K$6:$K$266,"Doing",$E$6:$E$266,"<>Scrum")>2,E40<>"Scrum"),"⚠ más de 2 en Doing","ok"))) | S40: =IF($K40="To Do",COUNTIF($K$6:$K40,"To Do"),"") | T40: =IF($K40="Doing",COUNTIF($K$6:$K40,"Doing"),"") | U40: =IF($K40="Done",COUNTIF($K$6:$K40,"Done"),"")
B41: T-036 | C41: HU-12 | D41: Loguear usuario | E41: Modelado UML | F41: Modelar la funcionalidad de HU-12 con el diagrama UML de secuencia del login y la renovación de la sesión | G41: Nicolás | H41: 1 | I41: 24/10 | J41: T-035 | K41: To Do | N41: Diagrama publicado en el repo o el lienzo | R41: =IF(AND(K41<>"To Do",L41<>"Sí"),"⚠ pasó a Doing sin DoR",IF(AND(K41="Done",O41<>"Sí"),"⚠ Done sin criterio cumplido",IF(AND(K41="Doing",COUNTIFS($G$6:$G$266,G41,$K$6:$K$266,"Doing",$E$6:$E$266,"<>Scrum")>2,E41<>"Scrum"),"⚠ más de 2 en Doing","ok"))) | S41: =IF($K41="To Do",COUNTIF($K$6:$K41,"To Do"),"") | T41: =IF($K41="Doing",COUNTIF($K$6:$K41,"Doing"),"") | U41: =IF($K41="Done",COUNTIF($K$6:$K41,"Done"),"")
B42: T-037 | C42: HU-12 | D42: Loguear usuario | E42: Base de datos | F42: Implementar las tablas asociadas a HU-12: usuario (hash de la clave, intentos, estado) | G42: Adiel | H42: 1 | I42: 24/10 | K42: Done | L42: Sí | M42: 22/10/2026 | N42: Migración fusionada, corre en base limpia y con datos, y se revierte | O42: Sí | P42: 22/10/2026 | Q42: PR #1 de Adiel (22/10) | R42: =IF(AND(K42<>"To Do",L42<>"Sí"),"⚠ pasó a Doing sin DoR",IF(AND(K42="Done",O42<>"Sí"),"⚠ Done sin criterio cumplido",IF(AND(K42="Doing",COUNTIFS($G$6:$G$266,G42,$K$6:$K$266,"Doing",$E$6:$E$266,"<>Scrum")>2,E42<>"Scrum"),"⚠ más de 2 en Doing","ok"))) | S42: =IF($K42="To Do",COUNTIF($K$6:$K42,"To Do"),"") | T42: =IF($K42="Doing",COUNTIF($K$6:$K42,"Doing"),"") | U42: =IF($K42="Done",COUNTIF($K$6:$K42,"Done"),"")
...

Sheet Vista del tablero
B2: Vista del tablero · se actualiza sola al cambiar el estado en el registro
B4: =CONCATENATE("To Do · ",COUNTIF('Tablero (To Do · Doing · Done)'!$K$6:$K$266,"To Do")) | E4: =CONCATENATE("Doing · ",COUNTIF('Tablero (To Do · Doing · Done)'!$K$6:$K$266,"Doing")) | H4: =CONCATENATE("Done · ",COUNTIF('Tablero (To Do · Doing · Done)'!$K$6:$K$266,"Done"))
B5: ID | C5: Tarea · responsable | E5: ID | F5: Tarea · responsable | H5: ID | I5: Tarea · responsable
B6: =IFERROR(INDEX('Tablero (To Do · Doing · Done)'!$B$6:$B$266,MATCH(1,'Tablero (To Do · Doing · Done)'!$S$6:$S$266,0)),"") | C6: =IFERROR(INDEX('Tablero (To Do · Doing · Done)'!$F$6:$F$266,MATCH(1,'Tablero (To Do · Doing · Done)'!$S$6:$S$266,0))&" · "&INDEX('Tablero (To Do · Doing · Done)'!$G$6:$G$266,MATCH(1,'Tablero (To Do · Doing · Done)'!$S$6:$S$266,0)),"") | E6: =IFERROR(INDEX('Tablero (To Do · Doing · Done)'!$B$6:$B$266,MATCH(1,'Tablero (To Do · Doing · Done)'!$T$6:$T$266,0)),"") | F6: =IFERROR(INDEX('Tablero (To Do · Doing · Done)'!$F$6:$F$266,MATCH(1,'Tablero (To Do · Doing · Done)'!$T$6:$T$266,0))&" · "&INDEX('Tablero (To Do · Doing · Done)'!$G$6:$G$266,MATCH(1,'Tablero (To Do · Doing · Done)'!$T$6:$T$266,0)),"") | H6: =IFERROR(INDEX('Tablero (To Do · Doing · Done)'!$B$6:$B$266,MATCH(1,'Tablero (To Do · Doing · Done)'!$U$6:$U$266,0)),"") | I6: =IFERROR(INDEX('Tablero (To Do · Doing · Done)'!$F$6:$F$266,MATCH(1,'Tablero (To Do · Doing · Done)'!$U$6:$U$266,0))&" · "&INDEX('Tablero (To Do · Doing · Done)'!$G$6:$G$266,MATCH(1,'Tablero (To Do · Doing · Done)'!$U$6:$U$266,0)),"")
B7: =IFERROR(INDEX('Tablero (To Do · Doing · Done)'!$B$6:$B$266,MATCH(2,'Tablero (To Do · Doing · Done)'!$S$6:$S$266,0)),"") | C7: =IFERROR(INDEX('Tablero (To Do · Doing · Done)'!$F$6:$F$266,MATCH(2,'Tablero (To Do · Doing · Done)'!$S$6:$S$266,0))&" · "&INDEX('Tablero (To Do · Doing · Done)'!$G$6:$G$266,MATCH(2,'Tablero (To Do · Doing · Done)'!$S$6:$S$266,0)),"") | E7: =IFERROR(INDEX('Tablero (To Do · Doing · Done)'!$B$6:$B$266,MATCH(2,'Tablero (To Do · Doing · Done)'!$T$6:$T$266,0)),"") | F7: =IFERROR(INDEX('Tablero (To Do · Doing · Done)'!$F$6:$F$266,MATCH(2,'Tablero (To Do · Doing · Done)'!$T$6:$T$266,0))&" · "&INDEX('Tablero (To Do · Doing · Done)'!$G$6:$G$266,MATCH(2,'Tablero (To Do · Doing · Done)'!$T$6:$T$266,0)),"") | H7: =IFERROR(INDEX('Tablero (To Do · Doing · Done)'!$B$6:$B$266,MATCH(2,'Tablero (To Do · Doing · Done)'!$U$6:$U$266,0)),"") | I7: =IFERROR(INDEX('Tablero (To Do · Doing · Done)'!$F$6:$F$266,MATCH(2,'Tablero (To Do · Doing · Done)'!$U$6:$U$266,0))&" · "&INDEX('Tablero (To Do · Doing · Done)'!$G$6:$G$266,MATCH(2,'Tablero (To Do · Doing · Done)'!$U$6:$U$266,0)),"")
B8: =IFERROR(INDEX('Tablero (To Do · Doing · Done)'!$B$6:$B$266,MATCH(3,'Tablero (To Do · Doing · Done)'!$S$6:$S$266,0)),"") | C8: =IFERROR(INDEX('Tablero (To Do · Doing · Done)'!$F$6:$F$266,MATCH(3,'Tablero (To Do · Doing · Done)'!$S$6:$S$266,0))&" · "&INDEX('Tablero (To Do · Doing · Done)'!$G$6:$G$266,MATCH(3,'Tablero (To Do · Doing · Done)'!$S$6:$S$266,0)),"") | E8: =IFERROR(INDEX('Tablero (To Do · Doing · Done)'!$B$6:$B$266,MATCH(3,'Tablero (To Do · Doing · Done)'!$T$6:$T$266,0)),"") | F8: =IFERROR(INDEX('Tablero (To Do · Doing · Done)'!$F$6:$F$266,MATCH(3,'Tablero (To Do · Doing · Done)'!$T$6:$T$266,0))&" · "&INDEX('Tablero (To Do · Doing · Done)'!$G$6:$G$266,MATCH(3,'Tablero (To Do · Doing · Done)'!$T$6:$T$266,0)),"") | H8: =IFERROR(INDEX('Tablero (To Do · Doing · Done)'!$B$6:$B$266,MATCH(3,'Tablero (To Do · Doing · Done)'!$U$6:$U$266,0)),"") | I8: =IFERROR(INDEX('Tablero (To Do · Doing · Done)'!$F$6:$F$266,MATCH(3,'Tablero (To Do · Doing · Done)'!$U$6:$U$266,0))&" · "&INDEX('Tablero (To Do · Doing · Done)'!$G$6:$G$266,MATCH(3,'Tablero (To Do · Doing · Done)'!$U$6:$U$266,0)),"")
B9: =IFERROR(INDEX('Tablero (To Do · Doing · Done)'!$B$6:$B$266,MATCH(4,'Tablero (To Do · Doing · Done)'!$S$6:$S$266,0)),"") | C9: =IFERROR(INDEX('Tablero (To Do · Doing · Done)'!$F$6:$F$266,MATCH(4,'Tablero (To Do · Doing · Done)'!$S$6:$S$266,0))&" · "&INDEX('Tablero (To Do · Doing · Done)'!$G$6:$G$266,MATCH(4,'Tablero (To Do · Doing · Done)'!$S$6:$S$266,0)),"") | E9: =IFERROR(INDEX('Tablero (To Do · Doing · Done)'!$B$6:$B$266,MATCH(4,'Tablero (To Do · Doing · Done)'!$T$6:$T$266,0)),"") | F9: =IFERROR(INDEX('Tablero (To Do · Doing · Done)'!$F$6:$F$266,MATCH(4,'Tablero (To Do · Doing · Done)'!$T$6:$T$266,0))&" · "&INDEX('Tablero (To Do · Doing · Done)'!$G$6:$G$266,MATCH(4,'Tablero (To Do · Doing · Done)'!$T$6:$T$266,0)),"") | H9: =IFERROR(INDEX('Tablero (To Do · Doing · Done)'!$B$6:$B$266,MATCH(4,'Tablero (To Do · Doing · Done)'!$U$6:$U$266,0)),"") | I9: =IFERROR(INDEX('Tablero (To Do · Doing · Done)'!$F$6:$F$266,MATCH(4,'Tablero (To Do · Doing · Done)'!$U$6:$U$266,0))&" · "&INDEX('Tablero (To Do · Doing · Done)'!$G$6:$G$266,MATCH(4,'Tablero (To Do · Doing · Done)'!$U$6:$U$266,0)),"")
B10: =IFERROR(INDEX('Tablero (To Do · Doing · Done)'!$B$6:$B$266,MATCH(5,'Tablero (To Do · Doing · Done)'!$S$6:$S$266,0)),"") | C10: =IFERROR(INDEX('Tablero (To Do · Doing · Done)'!$F$6:$F$266,MATCH(5,'Tablero (To Do · Doing · Done)'!$S$6:$S$266,0))&" · "&INDEX('Tablero (To Do · Doing · Done)'!$G$6:$G$266,MATCH(5,'Tablero (To Do · Doing · Done)'!$S$6:$S$266,0)),"") | E10: =IFERROR(INDEX('Tablero (To Do · Doing · Done)'!$B$6:$B$266,MATCH(5,'Tablero (To Do · Doing · Done)'!$T$6:$T$266,0)),"") | F10: =IFERROR(INDEX('Tablero (To Do · Doing · Done)'!$F$6:$F$266,MATCH(5,'Tablero (To Do · Doing · Done)'!$T$6:$T$266,0))&" · "&INDEX('Tablero (To Do · Doing · Done)'!$G$6:$G$266,MATCH(5,'Tablero (To Do · Doing · Done)'!$T$6:$T$266,0)),"") | H10: =IFERROR(INDEX('Tablero (To Do · Doing · Done)'!$B$6:$B$266,MATCH(5,'Tablero (To Do · Doing · Done)'!$U$6:$U$266,0)),"") | I10: =IFERROR(INDEX('Tablero (To Do · Doing · Done)'!$F$6:$F$266,MATCH(5,'Tablero (To Do · Doing · Done)'!$U$6:$U$266,0))&" · "&INDEX('Tablero (To Do · Doing · Done)'!$G$6:$G$266,MATCH(5,'Tablero (To Do · Doing · Done)'!$U$6:$U$266,0)),"")
B11: =IFERROR(INDEX('Tablero (To Do · Doing · Done)'!$B$6:$B$266,MATCH(6,'Tablero (To Do · Doing · Done)'!$S$6:$S$266,0)),"") | C11: =IFERROR(INDEX('Tablero (To Do · Doing · Done)'!$F$6:$F$266,MATCH(6,'Tablero (To Do · Doing · Done)'!$S$6:$S$266,0))&" · "&INDEX('Tablero (To Do · Doing · Done)'!$G$6:$G$266,MATCH(6,'Tablero (To Do · Doing · Done)'!$S$6:$S$266,0)),"") | E11: =IFERROR(INDEX('Tablero (To Do · Doing · Done)'!$B$6:$B$266,MATCH(6,'Tablero (To Do · Doing · Done)'!$T$6:$T$266,0)),"") | F11: =IFERROR(INDEX('Tablero (To Do · Doing · Done)'!$F$6:$F$266,MATCH(6,'Tablero (To Do · Doing · Done)'!$T$6:$T$266,0))&" · "&INDEX('Tablero (To Do · Doing · Done)'!$G$6:$G$266,MATCH(6,'Tablero (To Do · Doing · Done)'!$T$6:$T$266,0)),"") | H11: =IFERROR(INDEX('Tablero (To Do · Doing · Done)'!$B$6:$B$266,MATCH(6,'Tablero (To Do · Doing · Done)'!$U$6:$U$266,0)),"") | I11: =IFERROR(INDEX('Tablero (To Do · Doing · Done)'!$F$6:$F$266,MATCH(6,'Tablero (To Do · Doing · Done)'!$U$6:$U$266,0))&" · "&INDEX('Tablero (To Do · Doing · Done)'!$G$6:$G$266,MATCH(6,'Tablero (To Do · Doing · Done)'!$U$6:$U$266,0)),"")
B12: =IFERROR(INDEX('Tablero (To Do · Doing · Done)'!$B$6:$B$266,MATCH(7,'Tablero (To Do · Doing · Done)'!$S$6:$S$266,0)),"") | C12: =IFERROR(INDEX('Tablero (To Do · Doing · Done)'!$F$6:$F$266,MATCH(7,'Tablero (To Do · Doing · Done)'!$S$6:$S$266,0))&" · "&INDEX('Tablero (To Do · Doing · Done)'!$G$6:$G$266,MATCH(7,'Tablero (To Do · Doing · Done)'!$S$6:$S$266,0)),"") | E12: =IFERROR(INDEX('Tablero (To Do · Doing · Done)'!$B$6:$B$266,MATCH(7,'Tablero (To Do · Doing · Done)'!$T$6:$T$266,0)),"") | F12: =IFERROR(INDEX('Tablero (To Do · Doing · Done)'!$F$6:$F$266,MATCH(7,'Tablero (To Do · Doing · Done)'!$T$6:$T$266,0))&" · "&INDEX('Tablero (To Do · Doing · Done)'!$G$6:$G$266,MATCH(7,'Tablero (To Do · Doing · Done)'!$T$6:$T$266,0)),"") | H12: =IFERROR(INDEX('Tablero (To Do · Doing · Done)'!$B$6:$B$266,MATCH(7,'Tablero (To Do · Doing · Done)'!$U$6:$U$266,0)),"") | I12: =IFERROR(INDEX('Tablero (To Do · Doing · Done)'!$F$6:$F$266,MATCH(7,'Tablero (To Do · Doing · Done)'!$U$6:$U$266,0))&" · "&INDEX('Tablero (To Do · Doing · Done)'!$G$6:$G$266,MATCH(7,'Tablero (To Do · Doing · Done)'!$U$6:$U$266,0)),"")
B13: =IFERROR(INDEX('Tablero (To Do · Doing · Done)'!$B$6:$B$266,MATCH(8,'Tablero (To Do · Doing · Done)'!$S$6:$S$266,0)),"") | C13: =IFERROR(INDEX('Tablero (To Do · Doing · Done)'!$F$6:$F$266,MATCH(8,'Tablero (To Do · Doing · Done)'!$S$6:$S$266,0))&" · "&INDEX('Tablero (To Do · Doing · Done)'!$G$6:$G$266,MATCH(8,'Tablero (To Do · Doing · Done)'!$S$6:$S$266,0)),"") | E13: =IFERROR(INDEX('Tablero (To Do · Doing · Done)'!$B$6:$B$266,MATCH(8,'Tablero (To Do · Doing · Done)'!$T$6:$T$266,0)),"") | F13: =IFERROR(INDEX('Tablero (To Do · Doing · Done)'!$F$6:$F$266,MATCH(8,'Tablero (To Do · Doing · Done)'!$T$6:$T$266,0))&" · "&INDEX('Tablero (To Do · Doing · Done)'!$G$6:$G$266,MATCH(8,'Tablero (To Do · Doing · Done)'!$T$6:$T$266,0)),"") | H13: =IFERROR(INDEX('Tablero (To Do · Doing · Done)'!$B$6:$B$266,MATCH(8,'Tablero (To Do · Doing · Done)'!$U$6:$U$266,0)),"") | I13: =IFERROR(INDEX('Tablero (To Do · Doing · Done)'!$F$6:$F$266,MATCH(8,'Tablero (To Do · Doing · Done)'!$U$6:$U$266,0))&" · "&INDEX('Tablero (To Do · Doing · Done)'!$G$6:$G$266,MATCH(8,'Tablero (To Do · Doing · Done)'!$U$6:$U$266,0)),"")
B14: =IFERROR(INDEX('Tablero (To Do · Doing · Done)'!$B$6:$B$266,MATCH(9,'Tablero (To Do · Doing · Done)'!$S$6:$S$266,0)),"") | C14: =IFERROR(INDEX('Tablero (To Do · Doing · Done)'!$F$6:$F$266,MATCH(9,'Tablero (To Do · Doing · Done)'!$S$6:$S$266,0))&" · "&INDEX('Tablero (To Do · Doing · Done)'!$G$6:$G$266,MATCH(9,'Tablero (To Do · Doing · Done)'!$S$6:$S$266,0)),"") | E14: =IFERROR(INDEX('Tablero (To Do · Doing · Done)'!$B$6:$B$266,MATCH(9,'Tablero (To Do · Doing · Done)'!$T$6:$T$266,0)),"") | F14: =IFERROR(INDEX('Tablero (To Do · Doing · Done)'!$F$6:$F$266,MATCH(9,'Tablero (To Do · Doing · Done)'!$T$6:$T$266,0))&" · "&INDEX('Tablero (To Do · Doing · Done)'!$G$6:$G$266,MATCH(9,'Tablero (To Do · Doing · Done)'!$T$6:$T$266,0)),"") | H14: =IFERROR(INDEX('Tablero (To Do · Doing · Done)'!$B$6:$B$266,MATCH(9,'Tablero (To Do · Doing · Done)'!$U$6:$U$266,0)),"") | I14: =IFERROR(INDEX('Tablero (To Do · Doing · Done)'!$F$6:$F$266,MATCH(9,'Tablero (To Do · Doing · Done)'!$U$6:$U$266,0))&" · "&INDEX('Tablero (To Do · Doing · Done)'!$G$6:$G$266,MATCH(9,'Tablero (To Do · Doing · Done)'!$U$6:$U$266,0)),"")
B15: =IFERROR(INDEX('Tablero (To Do · Doing · Done)'!$B$6:$B$266,MATCH(10,'Tablero (To Do · Doing · Done)'!$S$6:$S$266,0)),"") | C15: =IFERROR(INDEX('Tablero (To Do · Doing · Done)'!$F$6:$F$266,MATCH(10,'Tablero (To Do · Doing · Done)'!$S$6:$S$266,0))&" · "&INDEX('Tablero (To Do · Doing · Done)'!$G$6:$G$266,MATCH(10,'Tablero (To Do · Doing · Done)'!$S$6:$S$266,0)),"") | E15: =IFERROR(INDEX('Tablero (To Do · Doing · Done)'!$B$6:$B$266,MATCH(10,'Tablero (To Do · Doing · Done)'!$T$6:$T$266,0)),"") | F15: =IFERROR(INDEX('Tablero (To Do · Doing · Done)'!$F$6:$F$266,MATCH(10,'Tablero (To Do · Doing · Done)'!$T$6:$T$266,0))&" · "&INDEX('Tablero (To Do · Doing · Done)'!$G$6:$G$266,MATCH(10,'Tablero (To Do · Doing · Done)'!$T$6:$T$266,0)),"") | H15: =IFERROR(INDEX('Tablero (To Do · Doing · Done)'!$B$6:$B$266,MATCH(10,'Tablero (To Do · Doing · Done)'!$U$6:$U$266,0)),"") | I15: =IFERROR(INDEX('Tablero (To Do · Doing · Done)'!$F$6:$F$266,MATCH(10,'Tablero (To Do · Doing · Done)'!$U$6:$U$266,0))&" · "&INDEX('Tablero (To Do · Doing · Done)'!$G$6:$G$266,MATCH(10,'Tablero (To Do · Doing · Done)'!$U$6:$U$266,0)),"")
B16: =IFERROR(INDEX('Tablero (To Do · Doing · Done)'!$B$6:$B$266,MATCH(11,'Tablero (To Do · Doing · Done)'!$S$6:$S$266,0)),"") | C16: =IFERROR(INDEX('Tablero (To Do · Doing · Done)'!$F$6:$F$266,MATCH(11,'Tablero (To Do · Doing · Done)'!$S$6:$S$266,0))&" · "&INDEX('Tablero (To Do · Doing · Done)'!$G$6:$G$266,MATCH(11,'Tablero (To Do · Doing · Done)'!$S$6:$S$266,0)),"") | E16: =IFERROR(INDEX('Tablero (To Do · Doing · Done)'!$B$6:$B$266,MATCH(11,'Tablero (To Do · Doing · Done)'!$T$6:$T$266,0)),"") | F16: =IFERROR(INDEX('Tablero (To Do · Doing · Done)'!$F$6:$F$266,MATCH(11,'Tablero (To Do · Doing · Done)'!$T$6:$T$266,0))&" · "&INDEX('Tablero (To Do · Doing · Done)'!$G$6:$G$266,MATCH(11,'Tablero (To Do · Doing · Done)'!$T$6:$T$266,0)),"") | H16: =IFERROR(INDEX('Tablero (To Do · Doing · Done)'!$B$6:$B$266,MATCH(11,'Tablero (To Do · Doing · Done)'!$U$6:$U$266,0)),"") | I16: =IFERROR(INDEX('Tablero (To Do · Doing · Done)'!$F$6:$F$266,MATCH(11,'Tablero (To Do · Doing · Done)'!$U$6:$U$266,0))&" · "&INDEX('Tablero (To Do · Doing · Done)'!$G$6:$G$266,MATCH(11,'Tablero (To Do · Doing · Done)'!$U$6:$U$266,0)),"")
B17: =IFERROR(INDEX('Tablero (To Do · Doing · Done)'!$B$6:$B$266,MATCH(12,'Tablero (To Do · Doing · Done)'!$S$6:$S$266,0)),"") | C17: =IFERROR(INDEX('Tablero (To Do · Doing · Done)'!$F$6:$F$266,MATCH(12,'Tablero (To Do · Doing · Done)'!$S$6:$S$266,0))&" · "&INDEX('Tablero (To Do · Doing · Done)'!$G$6:$G$266,MATCH(12,'Tablero (To Do · Doing · Done)'!$S$6:$S$266,0)),"") | E17: =IFERROR(INDEX('Tablero (To Do · Doing · Done)'!$B$6:$B$266,MATCH(12,'Tablero (To Do · Doing · Done)'!$T$6:$T$266,0)),"") | F17: =IFERROR(INDEX('Tablero (To Do · Doing · Done)'!$F$6:$F$266,MATCH(12,'Tablero (To Do · Doing · Done)'!$T$6:$T$266,0))&" · "&INDEX('Tablero (To Do · Doing · Done)'!$G$6:$G$266,MATCH(12,'Tablero (To Do · Doing · Done)'!$T$6:$T$266,0)),"") | H17: =IFERROR(INDEX('Tablero (To Do · Doing · Done)'!$B$6:$B$266,MATCH(12,'Tablero (To Do · Doing · Done)'!$U$6:$U$266,0)),"") | I17: =IFERROR(INDEX('Tablero (To Do · Doing · Done)'!$F$6:$F$266,MATCH(12,'Tablero (To Do · Doing · Done)'!$U$6:$U$266,0))&" · "&INDEX('Tablero (To Do · Doing · Done)'!$G$6:$G$266,MATCH(12,'Tablero (To Do · Doing · Done)'!$U$6:$U$266,0)),"")
B18: =IFERROR(INDEX('Tablero (To Do · Doing · Done)'!$B$6:$B$266,MATCH(13,'Tablero (To Do · Doing · Done)'!$S$6:$S$266,0)),"") | C18: =IFERROR(INDEX('Tablero (To Do · Doing · Done)'!$F$6:$F$266,MATCH(13,'Tablero (To Do · Doing · Done)'!$S$6:$S$266,0))&" · "&INDEX('Tablero (To Do · Doing · Done)'!$G$6:$G$266,MATCH(13,'Tablero (To Do · Doing · Done)'!$S$6:$S$266,0)),"") | E18: =IFERROR(INDEX('Tablero (To Do · Doing · Done)'!$B$6:$B$266,MATCH(13,'Tablero (To Do · Doing · Done)'!$T$6:$T$266,0)),"") | F18: =IFERROR(INDEX('Tablero (To Do · Doing · Done)'!$F$6:$F$266,MATCH(13,'Tablero (To Do · Doing · Done)'!$T$6:$T$266,0))&" · "&INDEX('Tablero (To Do · Doing · Done)'!$G$6:$G$266,MATCH(13,'Tablero (To Do · Doing · Done)'!$T$6:$T$266,0)),"") | H18: =IFERROR(INDEX('Tablero (To Do · Doing · Done)'!$B$6:$B$266,MATCH(13,'Tablero (To Do · Doing · Done)'!$U$6:$U$266,0)),"") | I18: =IFERROR(INDEX('Tablero (To Do · Doing · Done)'!$F$6:$F$266,MATCH(13,'Tablero (To Do · Doing · Done)'!$U$6:$U$266,0))&" · "&INDEX('Tablero (To Do · Doing · Done)'!$G$6:$G$266,MATCH(13,'Tablero (To Do · Doing · Done)'!$U$6:$U$266,0)),"")
B19: =IFERROR(INDEX('Tablero (To Do · Doing · Done)'!$B$6:$B$266,MATCH(14,'Tablero (To Do · Doing · Done)'!$S$6:$S$266,0)),"") | C19: =IFERROR(INDEX('Tablero (To Do · Doing · Done)'!$F$6:$F$266,MATCH(14,'Tablero (To Do · Doing · Done)'!$S$6:$S$266,0))&" · "&INDEX('Tablero (To Do · Doing · Done)'!$G$6:$G$266,MATCH(14,'Tablero (To Do · Doing · Done)'!$S$6:$S$266,0)),"") | E19: =IFERROR(INDEX('Tablero (To Do · Doing · Done)'!$B$6:$B$266,MATCH(14,'Tablero (To Do · Doing · Done)'!$T$6:$T$266,0)),"") | F19: =IFERROR(INDEX('Tablero (To Do · Doing · Done)'!$F$6:$F$266,MATCH(14,'Tablero (To Do · Doing · Done)'!$T$6:$T$266,0))&" · "&INDEX('Tablero (To Do · Doing · Done)'!$G$6:$G$266,MATCH(14,'Tablero (To Do · Doing · Done)'!$T$6:$T$266,0)),"") | H19: =IFERROR(INDEX('Tablero (To Do · Doing · Done)'!$B$6:$B$266,MATCH(14,'Tablero (To Do · Doing · Done)'!$U$6:$U$266,0)),"") | I19: =IFERROR(INDEX('Tablero (To Do · Doing · Done)'!$F$6:$F$266,MATCH(14,'Tablero (To Do · Doing · Done)'!$U$6:$U$266,0))&" · "&INDEX('Tablero (To Do · Doing · Done)'!$G$6:$G$266,MATCH(14,'Tablero (To Do · Doing · Done)'!$U$6:$U$266,0)),"")
B20: =IFERROR(INDEX('Tablero (To Do · Doing · Done)'!$B$6:$B$266,MATCH(15,'Tablero (To Do · Doing · Done)'!$S$6:$S$266,0)),"") | C20: =IFERROR(INDEX('Tablero (To Do · Doing · Done)'!$F$6:$F$266,MATCH(15,'Tablero (To Do · Doing · Done)'!$S$6:$S$266,0))&" · "&INDEX('Tablero (To Do · Doing · Done)'!$G$6:$G$266,MATCH(15,'Tablero (To Do · Doing · Done)'!$S$6:$S$266,0)),"") | E20: =IFERROR(INDEX('Tablero (To Do · Doing · Done)'!$B$6:$B$266,MATCH(15,'Tablero (To Do · Doing · Done)'!$T$6:$T$266,0)),"") | F20: =IFERROR(INDEX('Tablero (To Do · Doing · Done)'!$F$6:$F$266,MATCH(15,'Tablero (To Do · Doing · Done)'!$T$6:$T$266,0))&" · "&INDEX('Tablero (To Do · Doing · Done)'!$G$6:$G$266,MATCH(15,'Tablero (To Do · Doing · Done)'!$T$6:$T$266,0)),"") | H20: =IFERROR(INDEX('Tablero (To Do · Doing · Done)'!$B$6:$B$266,MATCH(15,'Tablero (To Do · Doing · Done)'!$U$6:$U$266,0)),"") | I20: =IFERROR(INDEX('Tablero (To Do · Doing · Done)'!$F$6:$F$266,MATCH(15,'Tablero (To Do · Doing · Done)'!$U$6:$U$266,0))&" · "&INDEX('Tablero (To Do · Doing · Done)'!$G$6:$G$266,MATCH(15,'Tablero (To Do · Doing · Done)'!$U$6:$U$266,0)),"")
B21: =IFERROR(INDEX('Tablero (To Do · Doing · Done)'!$B$6:$B$266,MATCH(16,'Tablero (To Do · Doing · Done)'!$S$6:$S$266,0)),"") | C21: =IFERROR(INDEX('Tablero (To Do · Doing · Done)'!$F$6:$F$266,MATCH(16,'Tablero (To Do · Doing · Done)'!$S$6:$S$266,0))&" · "&INDEX('Tablero (To Do · Doing · Done)'!$G$6:$G$266,MATCH(16,'Tablero (To Do · Doing · Done)'!$S$6:$S$266,0)),"") | E21: =IFERROR(INDEX('Tablero (To Do · Doing · Done)'!$B$6:$B$266,MATCH(16,'Tablero (To Do · Doing · Done)'!$T$6:$T$266,0)),"") | F21: =IFERROR(INDEX('Tablero (To Do · Doing · Done)'!$F$6:$F$266,MATCH(16,'Tablero (To Do · Doing · Done)'!$T$6:$T$266,0))&" · "&INDEX('Tablero (To Do · Doing · Done)'!$G$6:$G$266,MATCH(16,'Tablero (To Do · Doing · Done)'!$T$6:$T$266,0)),"") | H21: =IFERROR(INDEX('Tablero (To Do · Doing · Done)'!$B$6:$B$266,MATCH(16,'Tablero (To Do · Doing · Done)'!$U$6:$U$266,0)),"") | I21: =IFERROR(INDEX('Tablero (To Do · Doing · Done)'!$F$6:$F$266,MATCH(16,'Tablero (To Do · Doing · Done)'!$U$6:$U$266,0))&" · "&INDEX('Tablero (To Do · Doing · Done)'!$G$6:$G$266,MATCH(16,'Tablero (To Do · Doing · Done)'!$U$6:$U$266,0)),"")
B22: =IFERROR(INDEX('Tablero (To Do · Doing · Done)'!$B$6:$B$266,MATCH(17,'Tablero (To Do · Doing · Done)'!$S$6:$S$266,0)),"") | C22: =IFERROR(INDEX('Tablero (To Do · Doing · Done)'!$F$6:$F$266,MATCH(17,'Tablero (To Do · Doing · Done)'!$S$6:$S$266,0))&" · "&INDEX('Tablero (To Do · Doing · Done)'!$G$6:$G$266,MATCH(17,'Tablero (To Do · Doing · Done)'!$S$6:$S$266,0)),"") | E22: =IFERROR(INDEX('Tablero (To Do · Doing · Done)'!$B$6:$B$266,MATCH(17,'Tablero (To Do · Doing · Done)'!$T$6:$T$266,0)),"") | F22: =IFERROR(INDEX('Tablero (To Do · Doing · Done)'!$F$6:$F$266,MATCH(17,'Tablero (To Do · Doing · Done)'!$T$6:$T$266,0))&" · "&INDEX('Tablero (To Do · Doing · Done)'!$G$6:$G$266,MATCH(17,'Tablero (To Do · Doing · Done)'!$T$6:$T$266,0)),"") | H22: =IFERROR(INDEX('Tablero (To Do · Doing · Done)'!$B$6:$B$266,MATCH(17,'Tablero (To Do · Doing · Done)'!$U$6:$U$266,0)),"") | I22: =IFERROR(INDEX('Tablero (To Do · Doing · Done)'!$F$6:$F$266,MATCH(17,'Tablero (To Do · Doing · Done)'!$U$6:$U$266,0))&" · "&INDEX('Tablero (To Do · Doing · Done)'!$G$6:$G$266,MATCH(17,'Tablero (To Do · Doing · Done)'!$U$6:$U$266,0)),"")
B23: =IFERROR(INDEX('Tablero (To Do · Doing · Done)'!$B$6:$B$266,MATCH(18,'Tablero (To Do · Doing · Done)'!$S$6:$S$266,0)),"") | C23: =IFERROR(INDEX('Tablero (To Do · Doing · Done)'!$F$6:$F$266,MATCH(18,'Tablero (To Do · Doing · Done)'!$S$6:$S$266,0))&" · "&INDEX('Tablero (To Do · Doing · Done)'!$G$6:$G$266,MATCH(18,'Tablero (To Do · Doing · Done)'!$S$6:$S$266,0)),"") | E23: =IFERROR(INDEX('Tablero (To Do · Doing · Done)'!$B$6:$B$266,MATCH(18,'Tablero (To Do · Doing · Done)'!$T$6:$T$266,0)),"") | F23: =IFERROR(INDEX('Tablero (To Do · Doing · Done)'!$F$6:$F$266,MATCH(18,'Tablero (To Do · Doing · Done)'!$T$6:$T$266,0))&" · "&INDEX('Tablero (To Do · Doing · Done)'!$G$6:$G$266,MATCH(18,'Tablero (To Do · Doing · Done)'!$T$6:$T$266,0)),"") | H23: =IFERROR(INDEX('Tablero (To Do · Doing · Done)'!$B$6:$B$266,MATCH(18,'Tablero (To Do · Doing · Done)'!$U$6:$U$266,0)),"") | I23: =IFERROR(INDEX('Tablero (To Do · Doing · Done)'!$F$6:$F$266,MATCH(18,'Tablero (To Do · Doing · Done)'!$U$6:$U$266,0))&" · "&INDEX('Tablero (To Do · Doing · Done)'!$G$6:$G$266,MATCH(18,'Tablero (To Do · Doing · Done)'!$U$6:$U$266,0)),"")
B24: =IFERROR(INDEX('Tablero (To Do · Doing · Done)'!$B$6:$B$266,MATCH(19,'Tablero (To Do · Doing · Done)'!$S$6:$S$266,0)),"") | C24: =IFERROR(INDEX('Tablero (To Do · Doing · Done)'!$F$6:$F$266,MATCH(19,'Tablero (To Do · Doing · Done)'!$S$6:$S$266,0))&" · "&INDEX('Tablero (To Do · Doing · Done)'!$G$6:$G$266,MATCH(19,'Tablero (To Do · Doing · Done)'!$S$6:$S$266,0)),"") | E24: =IFERROR(INDEX('Tablero (To Do · Doing · Done)'!$B$6:$B$266,MATCH(19,'Tablero (To Do · Doing · Done)'!$T$6:$T$266,0)),"") | F24: =IFERROR(INDEX('Tablero (To Do · Doing · Done)'!$F$6:$F$266,MATCH(19,'Tablero (To Do · Doing · Done)'!$T$6:$T$266,0))&" · "&INDEX('Tablero (To Do · Doing · Done)'!$G$6:$G$266,MATCH(19,'Tablero (To Do · Doing · Done)'!$T$6:$T$266,0)),"") | H24: =IFERROR(INDEX('Tablero (To Do · Doing · Done)'!$B$6:$B$266,MATCH(19,'Tablero (To Do · Doing · Done)'!$U$6:$U$266,0)),"") | I24: =IFERROR(INDEX('Tablero (To Do · Doing · Done)'!$F$6:$F$266,MATCH(19,'Tablero (To Do · Doing · Done)'!$U$6:$U$266,0))&" · "&INDEX('Tablero (To Do · Doing · Done)'!$G$6:$G$266,MATCH(19,'Tablero (To Do · Doing · Done)'!$U$6:$U$266,0)),"")
