Workbook

Sheet Validar HU y tareas
B2: SIGRO · Sprint 1 · Historias de usuario y sus tareas (para validar)
B3: Cada integrante revisa las tareas de su área y marca «¿De acuerdo?». Si es «No», escribe qué cambiar. Lo validado pasa al tablero de GitHub.
B5: HU / ID | C5: Historia de usuario / tarea | D5: Fase / área | E5: Responsable | F5: Horas | G5: Estado | H5: Fecha límite | I5: Depende de | J5: ¿De acuerdo? | K5: Observación
B6: HU-01 · Crear proyecto 3 pts
B7: Como residente de obra, quiero crear el proyecto con su nombre y su plazo, para acotar todo el movimiento a ese periodo.
B8: T-001 | C8: Programar el endpoint para crear la obra, validando nombre y plazo obligatorios, fin ≥ inicio y estado inicial «en ejecución» | D8: Backend | E8: Adiel | F8: 2 | G8: Done | H8: 25/10 | K8: hecho en la API de Adiel (PR #1 fusionado a main), con pruebas
B9: T-002 | C9: Programar la pantalla web para crear la obra | D9: Web | E9: Fernando | F9: 2 | G9: Done | H9: 26/10 | K9: pantalla hecha con datos simulados; falta conectarla a la API real
B10: T-003 | C10: Conectar la pantalla «Crear la obra» con el endpoint real de la API | D10: Web | E10: Fernando | F10: 2 | G10: To Do | H10: 26/10 | I10: T-001, T-140
B11: T-004 | C11: Probar HU-01 en el ambiente de pruebas contra sus condiciones finales y aprobar su PR | D11: Pruebas | E11: Henry | F11: 1 | G11: To Do | H11: 27/10 | I11: T-001, T-002, T-003, T-139 | K11: alguien distinto del autor (T1, T5, T8)
B12: T-005 | C12: Aceptar HU-01 como Product Owner desde la interfaz y moverla a Done | D12: Aceptación | E12: Adiel | F12: 0.5 | G12: To Do | H12: 27/10 | I12: T-004 | K12: mueve la HU a Done
B13: HU-03 · Reportar la obra en semanas 3 pts
B14: Como residente de obra, quiero dividir el plazo de la obra en periodos semanales de control, para comparar lo consumido de un periodo con otro sin armar el corte a mano.
B15: T-006 | C15: Programar la generación automática de semanas al crear la obra y al ampliar el plazo, con sus pruebas | D15: Backend | E15: Adiel | F15: 2 | G15: To Do | H15: 25/10 | K15: confirmar si la API ya las genera
B16: T-007 | C16: Programar la tira de semanas en la web (cerrada, en curso, por venir) | D16: Web | E16: Fernando | F16: 2 | G16: Done | H16: 26/10 | K16: pantalla hecha con datos simulados; falta conectarla a la API real
B17: T-008 | C17: Conectar la tira de semanas con la API real | D17: Web | E17: Fernando | F17: 2 | G17: To Do | H17: 26/10 | I17: T-006, T-140
B18: T-009 | C18: Probar HU-03 en el ambiente de pruebas contra sus condiciones finales y aprobar su PR | D18: Pruebas | E18: Henry | F18: 1 | G18: To Do | H18: 27/10 | I18: T-006, T-007, T-008, T-139 | K18: alguien distinto del autor (T1, T5, T8)
B19: T-010 | C19: Aceptar HU-03 como Product Owner desde la interfaz y moverla a Done | D19: Aceptación | E19: Adiel | F19: 0.5 | G19: To Do | H19: 27/10 | I19: T-009 | K19: mueve la HU a Done
B20: HU-07 · Importar catálogo de insumos del S10 8 pts
B21: Como residente de obra, quiero importar el catálogo de insumos del S10, para evitar cargar a mano cientos de insumos.
B22: T-011 | C22: Programar el lector del PDF «Relación de insumos» del S10 en el microservicio | D22: Integraciones | E22: Fernando | F22: 4 | G22: Done | H22: 25/10 | K22: probado con el archivo real: 284 insumos, 0 fallidos, total exacto
B23: T-012 | C23: Programar el endpoint que aplica la importación: crear o actualizar insumos por código sin tocar saldos | D23: Backend | E23: Adiel | F23: 4 | G23: To Do | H23: 25/10
B24: T-013 | C24: Configurar la llamada de la API a Integraciones con el token de servicio en docker compose | D24: Backend | E24: Adiel | F24: 4 | G24: To Do | H24: 25/10 | K24: decisión B del 22/10
B25: T-014 | C25: Programar la pantalla web «Importar del S10» con el resumen de creados, actualizados y fallidos | D25: Web | E25: Fernando | F25: 4 | G25: Done | H25: 26/10 | K25: conectada al micro real
B26: T-015 | C26: Probar HU-07 en el ambiente de pruebas contra sus condiciones finales y aprobar su PR | D26: Pruebas | E26: Henry | F26: 1 | G26: To Do | H26: 27/10 | I26: T-011, T-012, T-013, T-014, T-139 | K26: alguien distinto del autor (T1, T5, T8)
B27: T-016 | C27: Aceptar HU-07 como Product Owner desde la interfaz y moverla a Done | D27: Aceptación | E27: Adiel | F27: 0.5 | G27: To Do | H27: 27/10 | I27: T-015 | K27: mueve la HU a Done
B28: HU-08 · Registrar insumos 5 pts
B29: Como almacenero, quiero registrar un insumo con información estandarizada, para identificarlo de la misma manera en todas las obras.
B30: T-017 | C30: Programar el endpoint del catálogo: generar código único, rechazar duplicados y marcar «por verificar» | D30: Backend | E30: Adiel | F30: 3 | G30: To Do | H30: 25/10
B31: T-018 | C31: Programar la pantalla web del catálogo para ver, dar de alta y editar insumos | D31: Web | E31: Fernando | F31: 3 | G31: Done | H31: 26/10 | K31: pantalla hecha con datos simulados; falta conectarla a la API real
B32: T-019 | C32: Conectar la pantalla del catálogo con la API real | D32: Web | E32: Fernando | F32: 3 | G32: To Do | H32: 26/10 | I32: T-017, T-140
B33: T-020 | C33: Probar HU-08 en el ambiente de pruebas contra sus condiciones finales y aprobar su PR | D33: Pruebas | E33: Henry | F33: 1 | G33: To Do | H33: 27/10 | I33: T-017, T-018, T-019, T-139 | K33: alguien distinto del autor (T1, T5, T8)
B34: T-021 | C34: Aceptar HU-08 como Product Owner desde la interfaz y moverla a Done | D34: Aceptación | E34: Adiel | F34: 0.5 | G34: To Do | H34: 27/10 | I34: T-020 | K34: mueve la HU a Done
B35: HU-12 · Loguear usuario 5 pts
B36: Como administrador, quiero entrar al sistema con mi usuario y contraseña, para que mis registros queden atribuidos a mí.
B37: T-022 | C37: Programar el login con Argon2id, sesión que caduca y se renueva, y bloqueo por intentos fallidos | D37: Backend | E37: Adiel | F37: 3 | G37: Done | H37: 25/10 | K37: hecho en la API de Adiel (PR #1 fusionado a main), con pruebas
B38: T-023 | C38: Programar la pantalla web de login y el manejo de la sesión | D38: Web | E38: Henry | F38: 3 | G38: To Do | H38: 26/10
B39: T-024 | C39: Programar el login en la app del almacenero | D39: Android | E39: Nicolás | F39: 3 | G39: To Do | H39: 26/10 | I39: T-141
B40: T-025 | C40: Probar HU-12 en el ambiente de pruebas contra sus condiciones finales y aprobar su PR | D40: Pruebas | E40: Henry | F40: 1 | G40: To Do | H40: 27/10 | I40: T-022, T-023, T-024, T-139 | K40: alguien distinto del autor (T1, T5, T8)
B41: T-026 | C41: Aceptar HU-12 como Product Owner desde la interfaz y moverla a Done | D41: Aceptación | E41: Adiel | F41: 0.5 | G41: To Do | H41: 27/10 | I41: T-025 | K41: mueve la HU a Done
B42: HU-13 · Asignar roles 5 pts
...

Sheet Tablero
B2: SIGRO · Sprint 1 · Tablero Scrum (15 al 28 de octubre)
B3: Cada HU se parte en tareas. To Do → Doing solo si la HU cumple la DoR (L1–L12). Doing → Done solo con la DoD (T1–T10 + condiciones finales). Meta: el lunes 27/10 (penúltimo día) todo en Done; el martes 28 es la Review.
B5: ID | C5: HU | D5: Historia | E5: Fase / área | F5: Tarea | G5: Responsable | H5: Horas | I5: Estado | J5: Fecha límite | K5: Evidencia / nota | L5: Depende de
B6: T-001 | C6: HU-01 | D6: Crear proyecto | E6: Backend | F6: Programar el endpoint para crear la obra, validando nombre y plazo obligatorios, fin ≥ inicio y estado inicial «en ejecución» | G6: Adiel | H6: 2 | I6: Done | J6: 25/10 | K6: hecho en la API de Adiel (PR #1 fusionado a main), con pruebas
B7: T-002 | C7: HU-01 | D7: Crear proyecto | E7: Web | F7: Programar la pantalla web para crear la obra | G7: Fernando | H7: 2 | I7: Done | J7: 26/10 | K7: pantalla hecha con datos simulados; falta conectarla a la API real
B8: T-003 | C8: HU-01 | D8: Crear proyecto | E8: Web | F8: Conectar la pantalla «Crear la obra» con el endpoint real de la API | G8: Fernando | H8: 2 | I8: To Do | J8: 26/10 | L8: T-001, T-140
B9: T-004 | C9: HU-01 | D9: Crear proyecto | E9: Pruebas | F9: Probar HU-01 en el ambiente de pruebas contra sus condiciones finales y aprobar su PR | G9: Henry | H9: 1 | I9: To Do | J9: 27/10 | K9: alguien distinto del autor (T1, T5, T8) | L9: T-001, T-002, T-003, T-139
B10: T-005 | C10: HU-01 | D10: Crear proyecto | E10: Aceptación | F10: Aceptar HU-01 como Product Owner desde la interfaz y moverla a Done | G10: Adiel | H10: 0.5 | I10: To Do | J10: 27/10 | K10: mueve la HU a Done | L10: T-004
B11: T-006 | C11: HU-03 | D11: Reportar la obra en semanas | E11: Backend | F11: Programar la generación automática de semanas al crear la obra y al ampliar el plazo, con sus pruebas | G11: Adiel | H11: 2 | I11: To Do | J11: 25/10 | K11: confirmar si la API ya las genera
B12: T-007 | C12: HU-03 | D12: Reportar la obra en semanas | E12: Web | F12: Programar la tira de semanas en la web (cerrada, en curso, por venir) | G12: Fernando | H12: 2 | I12: Done | J12: 26/10 | K12: pantalla hecha con datos simulados; falta conectarla a la API real
B13: T-008 | C13: HU-03 | D13: Reportar la obra en semanas | E13: Web | F13: Conectar la tira de semanas con la API real | G13: Fernando | H13: 2 | I13: To Do | J13: 26/10 | L13: T-006, T-140
B14: T-009 | C14: HU-03 | D14: Reportar la obra en semanas | E14: Pruebas | F14: Probar HU-03 en el ambiente de pruebas contra sus condiciones finales y aprobar su PR | G14: Henry | H14: 1 | I14: To Do | J14: 27/10 | K14: alguien distinto del autor (T1, T5, T8) | L14: T-006, T-007, T-008, T-139
B15: T-010 | C15: HU-03 | D15: Reportar la obra en semanas | E15: Aceptación | F15: Aceptar HU-03 como Product Owner desde la interfaz y moverla a Done | G15: Adiel | H15: 0.5 | I15: To Do | J15: 27/10 | K15: mueve la HU a Done | L15: T-009
B16: T-011 | C16: HU-07 | D16: Importar catálogo de insumos del S10 | E16: Integraciones | F16: Programar el lector del PDF «Relación de insumos» del S10 en el microservicio | G16: Fernando | H16: 4 | I16: Done | J16: 25/10 | K16: probado con el archivo real: 284 insumos, 0 fallidos, total exacto
B17: T-012 | C17: HU-07 | D17: Importar catálogo de insumos del S10 | E17: Backend | F17: Programar el endpoint que aplica la importación: crear o actualizar insumos por código sin tocar saldos | G17: Adiel | H17: 4 | I17: To Do | J17: 25/10
B18: T-013 | C18: HU-07 | D18: Importar catálogo de insumos del S10 | E18: Backend | F18: Configurar la llamada de la API a Integraciones con el token de servicio en docker compose | G18: Adiel | H18: 4 | I18: To Do | J18: 25/10 | K18: decisión B del 22/10
B19: T-014 | C19: HU-07 | D19: Importar catálogo de insumos del S10 | E19: Web | F19: Programar la pantalla web «Importar del S10» con el resumen de creados, actualizados y fallidos | G19: Fernando | H19: 4 | I19: Done | J19: 26/10 | K19: conectada al micro real
B20: T-015 | C20: HU-07 | D20: Importar catálogo de insumos del S10 | E20: Pruebas | F20: Probar HU-07 en el ambiente de pruebas contra sus condiciones finales y aprobar su PR | G20: Henry | H20: 1 | I20: To Do | J20: 27/10 | K20: alguien distinto del autor (T1, T5, T8) | L20: T-011, T-012, T-013, T-014, T-139
B21: T-016 | C21: HU-07 | D21: Importar catálogo de insumos del S10 | E21: Aceptación | F21: Aceptar HU-07 como Product Owner desde la interfaz y moverla a Done | G21: Adiel | H21: 0.5 | I21: To Do | J21: 27/10 | K21: mueve la HU a Done | L21: T-015
B22: T-017 | C22: HU-08 | D22: Registrar insumos | E22: Backend | F22: Programar el endpoint del catálogo: generar código único, rechazar duplicados y marcar «por verificar» | G22: Adiel | H22: 3 | I22: To Do | J22: 25/10
B23: T-018 | C23: HU-08 | D23: Registrar insumos | E23: Web | F23: Programar la pantalla web del catálogo para ver, dar de alta y editar insumos | G23: Fernando | H23: 3 | I23: Done | J23: 26/10 | K23: pantalla hecha con datos simulados; falta conectarla a la API real
B24: T-019 | C24: HU-08 | D24: Registrar insumos | E24: Web | F24: Conectar la pantalla del catálogo con la API real | G24: Fernando | H24: 3 | I24: To Do | J24: 26/10 | L24: T-017, T-140
B25: T-020 | C25: HU-08 | D25: Registrar insumos | E25: Pruebas | F25: Probar HU-08 en el ambiente de pruebas contra sus condiciones finales y aprobar su PR | G25: Henry | H25: 1 | I25: To Do | J25: 27/10 | K25: alguien distinto del autor (T1, T5, T8) | L25: T-017, T-018, T-019, T-139
B26: T-021 | C26: HU-08 | D26: Registrar insumos | E26: Aceptación | F26: Aceptar HU-08 como Product Owner desde la interfaz y moverla a Done | G26: Adiel | H26: 0.5 | I26: To Do | J26: 27/10 | K26: mueve la HU a Done | L26: T-020
B27: T-022 | C27: HU-12 | D27: Loguear usuario | E27: Backend | F27: Programar el login con Argon2id, sesión que caduca y se renueva, y bloqueo por intentos fallidos | G27: Adiel | H27: 3 | I27: Done | J27: 25/10 | K27: hecho en la API de Adiel (PR #1 fusionado a main), con pruebas
B28: T-023 | C28: HU-12 | D28: Loguear usuario | E28: Web | F28: Programar la pantalla web de login y el manejo de la sesión | G28: Henry | H28: 3 | I28: To Do | J28: 26/10
B29: T-024 | C29: HU-12 | D29: Loguear usuario | E29: Android | F29: Programar el login en la app del almacenero | G29: Nicolás | H29: 3 | I29: To Do | J29: 26/10 | L29: T-141
B30: T-025 | C30: HU-12 | D30: Loguear usuario | E30: Pruebas | F30: Probar HU-12 en el ambiente de pruebas contra sus condiciones finales y aprobar su PR | G30: Henry | H30: 1 | I30: To Do | J30: 27/10 | K30: alguien distinto del autor (T1, T5, T8) | L30: T-022, T-023, T-024, T-139
B31: T-026 | C31: HU-12 | D31: Loguear usuario | E31: Aceptación | F31: Aceptar HU-12 como Product Owner desde la interfaz y moverla a Done | G31: Adiel | H31: 0.5 | I31: To Do | J31: 27/10 | K31: mueve la HU a Done | L31: T-025
B32: T-027 | C32: HU-13 | D32: Asignar roles | E32: Backend | F32: Programar los roles y verificar sus permisos en el servidor | G32: Adiel | H32: 4 | I32: Done | J32: 25/10 | K32: hecho en la API de Adiel (PR #1 fusionado a main), con pruebas
B33: T-028 | C33: HU-13 | D33: Asignar roles | E33: Web | F33: Programar la pantalla web para crear usuarios, asignar su rol y darlos de baja | G33: Henry | H33: 4 | I33: To Do | J33: 26/10
B34: T-029 | C34: HU-13 | D34: Asignar roles | E34: Pruebas | F34: Probar HU-13 en el ambiente de pruebas contra sus condiciones finales y aprobar su PR | G34: Fernando | H34: 1 | I34: To Do | J34: 27/10 | K34: alguien distinto del autor (T1, T5, T8) | L34: T-027, T-028, T-139
B35: T-030 | C35: HU-13 | D35: Asignar roles | E35: Aceptación | F35: Aceptar HU-13 como Product Owner desde la interfaz y moverla a Done | G35: Adiel | H35: 0.5 | I35: To Do | J35: 27/10 | K35: mueve la HU a Done | L35: T-029
B36: T-031 | C36: HU-14 | D36: Asignar usuarios a obras | E36: Backend | F36: Programar el endpoint para asignar usuarios a obras | G36: Adiel | H36: 2 | I36: Done | J36: 25/10 | K36: hecho en la API de Adiel (PR #1 fusionado a main), con pruebas
B37: T-032 | C37: HU-14 | D37: Asignar usuarios a obras | E37: Web | F37: Programar la pantalla web para asignar usuarios a obras | G37: Henry | H37: 2 | I37: To Do | J37: 26/10
B38: T-033 | C38: HU-14 | D38: Asignar usuarios a obras | E38: Pruebas | F38: Probar HU-14 en el ambiente de pruebas contra sus condiciones finales y aprobar su PR | G38: Fernando | H38: 1 | I38: To Do | J38: 27/10 | K38: alguien distinto del autor (T1, T5, T8) | L38: T-031, T-032, T-139
B39: T-034 | C39: HU-14 | D39: Asignar usuarios a obras | E39: Aceptación | F39: Aceptar HU-14 como Product Owner desde la interfaz y moverla a Done | G39: Adiel | H39: 0.5 | I39: To Do | J39: 27/10 | K39: mueve la HU a Done | L39: T-033
B40: T-035 | C40: HU-15 | D40: Autorizar celular de la obra | E40: Backend | F40: Programar el registro de dispositivos autorizados por obra (máximo dos) y el rechazo del no autorizado | G40: Adiel | H40: 3 | I40: Done | J40: 25/10 | K40: hecho en la API de Adiel (PR #1 fusionado a main), con pruebas
B41: T-036 | C41: HU-15 | D41: Autorizar celular de la obra | E41: Android | F41: Programar en la app la generación del código del dispositivo en la primera instalación | G41: Nicolás | H41: 3 | I41: To Do | J41: 26/10 | L41: T-141
B42: T-037 | C42: HU-15 | D42: Autorizar celular de la obra | E42: Web | F42: Programar la pantalla web para autorizar o cambiar el celular de la obra | G42: Henry | H42: 3 | I42: To Do | J42: 26/10
...

Sheet Resumen
B2: Resumen del tablero (se actualiza solo)
B4: Responsable | C4: To Do | D4: Doing | E4: Done | F4: Horas pendientes | G4: Doing ≤ 2 (sin Scrum)
B5: Fernando | C5: =COUNTIFS(Tablero!$G$6:$G$161,B5,Tablero!$I$6:$I$161,"To Do") | D5: =COUNTIFS(Tablero!$G$6:$G$161,B5,Tablero!$I$6:$I$161,"Doing") | E5: =COUNTIFS(Tablero!$G$6:$G$161,B5,Tablero!$I$6:$I$161,"Done") | F5: =SUMIFS(Tablero!$H$6:$H$161,Tablero!$G$6:$G$161,B5,Tablero!$I$6:$I$161,"<>Done") | G5: =IF(COUNTIFS(Tablero!$G$6:$G$161,B5,Tablero!$I$6:$I$161,"Doing",Tablero!$E$6:$E$161,"<>Scrum")<=2,"ok","demasiado en curso")
B6: Henry | C6: =COUNTIFS(Tablero!$G$6:$G$161,B6,Tablero!$I$6:$I$161,"To Do") | D6: =COUNTIFS(Tablero!$G$6:$G$161,B6,Tablero!$I$6:$I$161,"Doing") | E6: =COUNTIFS(Tablero!$G$6:$G$161,B6,Tablero!$I$6:$I$161,"Done") | F6: =SUMIFS(Tablero!$H$6:$H$161,Tablero!$G$6:$G$161,B6,Tablero!$I$6:$I$161,"<>Done") | G6: =IF(COUNTIFS(Tablero!$G$6:$G$161,B6,Tablero!$I$6:$I$161,"Doing",Tablero!$E$6:$E$161,"<>Scrum")<=2,"ok","demasiado en curso")
B7: Nicolás | C7: =COUNTIFS(Tablero!$G$6:$G$161,B7,Tablero!$I$6:$I$161,"To Do") | D7: =COUNTIFS(Tablero!$G$6:$G$161,B7,Tablero!$I$6:$I$161,"Doing") | E7: =COUNTIFS(Tablero!$G$6:$G$161,B7,Tablero!$I$6:$I$161,"Done") | F7: =SUMIFS(Tablero!$H$6:$H$161,Tablero!$G$6:$G$161,B7,Tablero!$I$6:$I$161,"<>Done") | G7: =IF(COUNTIFS(Tablero!$G$6:$G$161,B7,Tablero!$I$6:$I$161,"Doing",Tablero!$E$6:$E$161,"<>Scrum")<=2,"ok","demasiado en curso")
B8: Adiel | C8: =COUNTIFS(Tablero!$G$6:$G$161,B8,Tablero!$I$6:$I$161,"To Do") | D8: =COUNTIFS(Tablero!$G$6:$G$161,B8,Tablero!$I$6:$I$161,"Doing") | E8: =COUNTIFS(Tablero!$G$6:$G$161,B8,Tablero!$I$6:$I$161,"Done") | F8: =SUMIFS(Tablero!$H$6:$H$161,Tablero!$G$6:$G$161,B8,Tablero!$I$6:$I$161,"<>Done") | G8: =IF(COUNTIFS(Tablero!$G$6:$G$161,B8,Tablero!$I$6:$I$161,"Doing",Tablero!$E$6:$E$161,"<>Scrum")<=2,"ok","demasiado en curso")
B9: Total | C9: =SUM(C5:C8) | D9: =SUM(D5:D8) | E9: =SUM(E5:E8) | F9: =SUM(F5:F8)
B12: HU | C12: Historia | D12: Puntos | E12: Tareas | F12: Tareas Done | G12: % avance | H12: Estado de la HU
B13: HU-01 | C13: Crear proyecto | D13: 3 | E13: =COUNTIF(Tablero!$C$6:$C$161,B13) | F13: =COUNTIFS(Tablero!$C$6:$C$161,B13,Tablero!$I$6:$I$161,"Done") | G13: =IF(E13=0,0,F13/E13) | H13: =IF(COUNTIFS(Tablero!$C$6:$C$161,B13,Tablero!$E$6:$E$161,"Aceptación",Tablero!$I$6:$I$161,"Done")=1,"Done",IF(F13>0,"Doing","To Do"))
B14: HU-03 | C14: Reportar la obra en semanas | D14: 3 | E14: =COUNTIF(Tablero!$C$6:$C$161,B14) | F14: =COUNTIFS(Tablero!$C$6:$C$161,B14,Tablero!$I$6:$I$161,"Done") | G14: =IF(E14=0,0,F14/E14) | H14: =IF(COUNTIFS(Tablero!$C$6:$C$161,B14,Tablero!$E$6:$E$161,"Aceptación",Tablero!$I$6:$I$161,"Done")=1,"Done",IF(F14>0,"Doing","To Do"))
B15: HU-07 | C15: Importar catálogo de insumos del S10 | D15: 8 | E15: =COUNTIF(Tablero!$C$6:$C$161,B15) | F15: =COUNTIFS(Tablero!$C$6:$C$161,B15,Tablero!$I$6:$I$161,"Done") | G15: =IF(E15=0,0,F15/E15) | H15: =IF(COUNTIFS(Tablero!$C$6:$C$161,B15,Tablero!$E$6:$E$161,"Aceptación",Tablero!$I$6:$I$161,"Done")=1,"Done",IF(F15>0,"Doing","To Do"))
B16: HU-08 | C16: Registrar insumos | D16: 5 | E16: =COUNTIF(Tablero!$C$6:$C$161,B16) | F16: =COUNTIFS(Tablero!$C$6:$C$161,B16,Tablero!$I$6:$I$161,"Done") | G16: =IF(E16=0,0,F16/E16) | H16: =IF(COUNTIFS(Tablero!$C$6:$C$161,B16,Tablero!$E$6:$E$161,"Aceptación",Tablero!$I$6:$I$161,"Done")=1,"Done",IF(F16>0,"Doing","To Do"))
B17: HU-12 | C17: Loguear usuario | D17: 5 | E17: =COUNTIF(Tablero!$C$6:$C$161,B17) | F17: =COUNTIFS(Tablero!$C$6:$C$161,B17,Tablero!$I$6:$I$161,"Done") | G17: =IF(E17=0,0,F17/E17) | H17: =IF(COUNTIFS(Tablero!$C$6:$C$161,B17,Tablero!$E$6:$E$161,"Aceptación",Tablero!$I$6:$I$161,"Done")=1,"Done",IF(F17>0,"Doing","To Do"))
B18: HU-13 | C18: Asignar roles | D18: 5 | E18: =COUNTIF(Tablero!$C$6:$C$161,B18) | F18: =COUNTIFS(Tablero!$C$6:$C$161,B18,Tablero!$I$6:$I$161,"Done") | G18: =IF(E18=0,0,F18/E18) | H18: =IF(COUNTIFS(Tablero!$C$6:$C$161,B18,Tablero!$E$6:$E$161,"Aceptación",Tablero!$I$6:$I$161,"Done")=1,"Done",IF(F18>0,"Doing","To Do"))
B19: HU-14 | C19: Asignar usuarios a obras | D19: 3 | E19: =COUNTIF(Tablero!$C$6:$C$161,B19) | F19: =COUNTIFS(Tablero!$C$6:$C$161,B19,Tablero!$I$6:$I$161,"Done") | G19: =IF(E19=0,0,F19/E19) | H19: =IF(COUNTIFS(Tablero!$C$6:$C$161,B19,Tablero!$E$6:$E$161,"Aceptación",Tablero!$I$6:$I$161,"Done")=1,"Done",IF(F19>0,"Doing","To Do"))
B20: HU-15 | C20: Autorizar celular de la obra | D20: 5 | E20: =COUNTIF(Tablero!$C$6:$C$161,B20) | F20: =COUNTIFS(Tablero!$C$6:$C$161,B20,Tablero!$I$6:$I$161,"Done") | G20: =IF(E20=0,0,F20/E20) | H20: =IF(COUNTIFS(Tablero!$C$6:$C$161,B20,Tablero!$E$6:$E$161,"Aceptación",Tablero!$I$6:$I$161,"Done")=1,"Done",IF(F20>0,"Doing","To Do"))
B21: HU-16 | C21: Importar precios unitarios | D21: 8 | E21: =COUNTIF(Tablero!$C$6:$C$161,B21) | F21: =COUNTIFS(Tablero!$C$6:$C$161,B21,Tablero!$I$6:$I$161,"Done") | G21: =IF(E21=0,0,F21/E21) | H21: =IF(COUNTIFS(Tablero!$C$6:$C$161,B21,Tablero!$E$6:$E$161,"Aceptación",Tablero!$I$6:$I$161,"Done")=1,"Done",IF(F21>0,"Doing","To Do"))
B22: HU-17 | C22: Convertir unidades (kg a varillas) | D22: 3 | E22: =COUNTIF(Tablero!$C$6:$C$161,B22) | F22: =COUNTIFS(Tablero!$C$6:$C$161,B22,Tablero!$I$6:$I$161,"Done") | G22: =IF(E22=0,0,F22/E22) | H22: =IF(COUNTIFS(Tablero!$C$6:$C$161,B22,Tablero!$E$6:$E$161,"Aceptación",Tablero!$I$6:$I$161,"Done")=1,"Done",IF(F22>0,"Doing","To Do"))
B23: HU-19 | C23: Importar requerimiento de la obra | D23: 5 | E23: =COUNTIF(Tablero!$C$6:$C$161,B23) | F23: =COUNTIFS(Tablero!$C$6:$C$161,B23,Tablero!$I$6:$I$161,"Done") | G23: =IF(E23=0,0,F23/E23) | H23: =IF(COUNTIFS(Tablero!$C$6:$C$161,B23,Tablero!$E$6:$E$161,"Aceptación",Tablero!$I$6:$I$161,"Done")=1,"Done",IF(F23>0,"Doing","To Do"))
B24: HU-23 | C24: Consultar cuánto se compró y consumió | D24: 5 | E24: =COUNTIF(Tablero!$C$6:$C$161,B24) | F24: =COUNTIFS(Tablero!$C$6:$C$161,B24,Tablero!$I$6:$I$161,"Done") | G24: =IF(E24=0,0,F24/E24) | H24: =IF(COUNTIFS(Tablero!$C$6:$C$161,B24,Tablero!$E$6:$E$161,"Aceptación",Tablero!$I$6:$I$161,"Done")=1,"Done",IF(F24>0,"Doing","To Do"))
... B41: HU-63 | C41: Tomar asistencia | D41: 5 | E41: =COUNTIF(Tablero!$C$6:$C$161,B41) | F41: =COUNTIFS(Tablero!$C$6:$C$161,B41,Tablero!$I$6:$I$161,"Done") | G41: =IF(E41=0,0,F41/E41) | H41: =IF(COUNTIFS(Tablero!$C$6:$C$161,B41,Tablero!$E$6:$E$161,"Aceptación",Tablero!$I$6:$I$161,"Done")=1,"Done",IF(F41>0,"Doing","To Do"))
B42: Puntos terminados (velocidad) | D42: =SUMIF(H13:H41,"Done",D13:D41)
B43: Puntos comprometidos | D43: =SUM(D13:D41)

Sheet Reglas del tablero
B2: Reglas del tablero
B4: Columnas | C4: To Do → Doing → Done. Una tarjeta por TAREA; la HU queda Done cuando su tarea «Aceptar … como Product Owner» pasa a Done.
B5: Criterio de las tareas | C5: Una tarea entra solo si produce algo que la DoD verifica o si desbloquea a otra. Lo ya hecho se cuenta una vez; el diseño de pantallas y el UML se hacen por flujo, no por HU.
B6: Entrada a Doing (DoR) | C6: Una tarea solo pasa a Doing si su HU cumple L1–L12: entre ellos recursos identificados, requisitos técnicos y accesos de red.
B7: Entrada a Done (DoD) | C7: La tarea de cierre pasa a Done solo con T1–T10 y las condiciones finales de la tarjeta verificadas desde la interfaz y aceptadas por el PO.
B8: Límite de trabajo en curso | C8: Máximo 2 tareas en Doing por persona: se termina antes de empezar otra.
B9: Daily Scrum | C9: Todos los días, 15 minutos, frente al tablero: qué terminé, qué hago hoy, qué me bloquea. Se mueve la tarjeta en la reunión, no después.
B10: Fecha de cierre | C10: Lunes 27/10 (penúltimo día): todo en Done. Martes 28/10: Sprint Review y Retrospectiva. Lo que no llegue vuelve al Product Backlog, no se arrastra a escondidas.
B11: Bloqueos | C11: Las tareas «Conectar… a la API real» dependen del ClienteHttp (Henry) y del ambiente de pruebas (Adiel): esas dos van primero.
B12: Reparto | C12: Web: Fernando y Henry · App Android: Nicolás · Backend: Adiel (además PO) · Integraciones: Fernando (además Scrum Master).
